[2022-10-05 21:26:32,592] {taskinstance.py:1159} INFO - Dependencies all met for <TaskInstance: load_rappers_dag.load_rappers scheduled__2022-10-05T20:00:00+00:00 [queued]>
[2022-10-05 21:26:32,700] {taskinstance.py:1159} INFO - Dependencies all met for <TaskInstance: load_rappers_dag.load_rappers scheduled__2022-10-05T20:00:00+00:00 [queued]>
[2022-10-05 21:26:32,700] {taskinstance.py:1356} INFO - 
--------------------------------------------------------------------------------
[2022-10-05 21:26:32,700] {taskinstance.py:1357} INFO - Starting attempt 1 of 1
[2022-10-05 21:26:32,700] {taskinstance.py:1358} INFO - 
--------------------------------------------------------------------------------
[2022-10-05 21:26:32,781] {taskinstance.py:1377} INFO - Executing <Task(BashOperator): load_rappers> on 2022-10-05 20:00:00+00:00
[2022-10-05 21:26:32,809] {standard_task_runner.py:52} INFO - Started process 3252 to run task
[2022-10-05 21:26:32,821] {standard_task_runner.py:79} INFO - Running: ['***', 'tasks', 'run', 'load_rappers_dag', 'load_rappers', 'scheduled__2022-10-05T20:00:00+00:00', '--job-id', '38', '--raw', '--subdir', 'DAGS_FOLDER/load_rappers_dag.py', '--cfg-path', '/tmp/tmpm9zmi07b', '--error-file', '/tmp/tmpoxst7fcz']
[2022-10-05 21:26:32,840] {standard_task_runner.py:80} INFO - Job 38: Subtask load_rappers
[2022-10-05 21:26:33,444] {task_command.py:369} INFO - Running <TaskInstance: load_rappers_dag.load_rappers scheduled__2022-10-05T20:00:00+00:00 [running]> on host 39b88b75de04
[2022-10-05 21:26:33,994] {taskinstance.py:1571} INFO - Exporting the following env vars:
AIRFLOW_CTX_DAG_OWNER=***
AIRFLOW_CTX_DAG_ID=load_rappers_dag
AIRFLOW_CTX_TASK_ID=load_rappers
AIRFLOW_CTX_EXECUTION_DATE=2022-10-05T20:00:00+00:00
AIRFLOW_CTX_TRY_NUMBER=1
AIRFLOW_CTX_DAG_RUN_ID=scheduled__2022-10-05T20:00:00+00:00
[2022-10-05 21:26:34,003] {subprocess.py:62} INFO - Tmp dir root location: 
 /tmp
[2022-10-05 21:26:34,005] {subprocess.py:74} INFO - Running command: ['bash', '-c', 'python ${AIRFLOW_HOME}/scripts/load_rappers.py']
[2022-10-05 21:26:34,105] {subprocess.py:85} INFO - Output:
[2022-10-05 21:31:28,973] {subprocess.py:92} INFO - Compiling artist list...
[2022-10-05 21:31:29,020] {subprocess.py:92} INFO - Loading artists...
[2022-10-05 21:31:29,021] {subprocess.py:92} INFO - 502 artists loaded in 136.51 seconds
[2022-10-05 21:31:29,021] {subprocess.py:92} INFO - Loading tracks...
[2022-10-05 21:31:29,021] {subprocess.py:92} INFO - 2497 tracks loaded in 136.77 seconds
[2022-10-05 21:31:29,021] {subprocess.py:92} INFO - Traceback (most recent call last):
[2022-10-05 21:31:29,022] {subprocess.py:92} INFO -   File "/home/***/.local/lib/python3.7/site-packages/sqlalchemy/engine/base.py", line 3141, in _wrap_pool_connect
[2022-10-05 21:31:29,022] {subprocess.py:92} INFO -     return fn()
[2022-10-05 21:31:29,022] {subprocess.py:92} INFO -   File "/home/***/.local/lib/python3.7/site-packages/sqlalchemy/pool/base.py", line 301, in connect
[2022-10-05 21:31:29,022] {subprocess.py:92} INFO -     return _ConnectionFairy._checkout(self)
[2022-10-05 21:31:29,022] {subprocess.py:92} INFO -   File "/home/***/.local/lib/python3.7/site-packages/sqlalchemy/pool/base.py", line 755, in _checkout
[2022-10-05 21:31:29,022] {subprocess.py:92} INFO -     fairy = _ConnectionRecord.checkout(pool)
[2022-10-05 21:31:29,022] {subprocess.py:92} INFO -   File "/home/***/.local/lib/python3.7/site-packages/sqlalchemy/pool/base.py", line 419, in checkout
[2022-10-05 21:31:29,022] {subprocess.py:92} INFO -     rec = pool._do_get()
[2022-10-05 21:31:29,022] {subprocess.py:92} INFO -   File "/home/***/.local/lib/python3.7/site-packages/sqlalchemy/pool/impl.py", line 145, in _do_get
[2022-10-05 21:31:29,023] {subprocess.py:92} INFO -     self._dec_overflow()
[2022-10-05 21:31:29,023] {subprocess.py:92} INFO -   File "/home/***/.local/lib/python3.7/site-packages/sqlalchemy/util/langhelpers.py", line 72, in __exit__
[2022-10-05 21:31:29,023] {subprocess.py:92} INFO -     with_traceback=exc_tb,
[2022-10-05 21:31:29,023] {subprocess.py:92} INFO -   File "/home/***/.local/lib/python3.7/site-packages/sqlalchemy/util/compat.py", line 211, in raise_
[2022-10-05 21:31:29,023] {subprocess.py:92} INFO -     raise exception
[2022-10-05 21:31:29,023] {subprocess.py:92} INFO -   File "/home/***/.local/lib/python3.7/site-packages/sqlalchemy/pool/impl.py", line 142, in _do_get
[2022-10-05 21:31:29,023] {subprocess.py:92} INFO -     return self._create_connection()
[2022-10-05 21:31:29,023] {subprocess.py:92} INFO -   File "/home/***/.local/lib/python3.7/site-packages/sqlalchemy/pool/base.py", line 247, in _create_connection
[2022-10-05 21:31:29,023] {subprocess.py:92} INFO -     return _ConnectionRecord(self)
[2022-10-05 21:31:29,023] {subprocess.py:92} INFO -   File "/home/***/.local/lib/python3.7/site-packages/sqlalchemy/pool/base.py", line 362, in __init__
[2022-10-05 21:31:29,023] {subprocess.py:92} INFO -     self.__connect(first_connect_check=True)
[2022-10-05 21:31:29,023] {subprocess.py:92} INFO -   File "/home/***/.local/lib/python3.7/site-packages/sqlalchemy/pool/base.py", line 605, in __connect
[2022-10-05 21:31:29,023] {subprocess.py:92} INFO -     pool.logger.debug("Error on connect(): %s", e)
[2022-10-05 21:31:29,023] {subprocess.py:92} INFO -   File "/home/***/.local/lib/python3.7/site-packages/sqlalchemy/util/langhelpers.py", line 72, in __exit__
[2022-10-05 21:31:29,023] {subprocess.py:92} INFO -     with_traceback=exc_tb,
[2022-10-05 21:31:29,023] {subprocess.py:92} INFO -   File "/home/***/.local/lib/python3.7/site-packages/sqlalchemy/util/compat.py", line 211, in raise_
[2022-10-05 21:31:29,023] {subprocess.py:92} INFO -     raise exception
[2022-10-05 21:31:29,023] {subprocess.py:92} INFO -   File "/home/***/.local/lib/python3.7/site-packages/sqlalchemy/pool/base.py", line 599, in __connect
[2022-10-05 21:31:29,023] {subprocess.py:92} INFO -     connection = pool._invoke_creator(self)
[2022-10-05 21:31:29,023] {subprocess.py:92} INFO -   File "/home/***/.local/lib/python3.7/site-packages/sqlalchemy/engine/create.py", line 578, in connect
[2022-10-05 21:31:29,023] {subprocess.py:92} INFO -     return dialect.connect(*cargs, **cparams)
[2022-10-05 21:31:29,023] {subprocess.py:92} INFO -   File "/home/***/.local/lib/python3.7/site-packages/sqlalchemy/engine/default.py", line 583, in connect
[2022-10-05 21:31:29,023] {subprocess.py:92} INFO -     return self.dbapi.connect(*cargs, **cparams)
[2022-10-05 21:31:29,023] {subprocess.py:92} INFO -   File "/home/***/.local/lib/python3.7/site-packages/psycopg2/__init__.py", line 122, in connect
[2022-10-05 21:31:29,023] {subprocess.py:92} INFO -     conn = _connect(dsn, connection_factory=connection_factory, **kwasync)
[2022-10-05 21:31:29,023] {subprocess.py:92} INFO - psycopg2.OperationalError: connection to server at "127.0.0.1", port 5432 failed: Connection refused
[2022-10-05 21:31:29,023] {subprocess.py:92} INFO - 	Is the server running on that host and accepting TCP/IP connections?
[2022-10-05 21:31:29,024] {subprocess.py:92} INFO - 
[2022-10-05 21:31:29,024] {subprocess.py:92} INFO - 
[2022-10-05 21:31:29,024] {subprocess.py:92} INFO - The above exception was the direct cause of the following exception:
[2022-10-05 21:31:29,024] {subprocess.py:92} INFO - 
[2022-10-05 21:31:29,024] {subprocess.py:92} INFO - Traceback (most recent call last):
[2022-10-05 21:31:29,024] {subprocess.py:92} INFO -   File "/opt/***/scripts/load_rappers.py", line 64, in <module>
[2022-10-05 21:31:29,024] {subprocess.py:92} INFO -     Base.metadata.create_all(engine)
[2022-10-05 21:31:29,024] {subprocess.py:92} INFO -   File "/home/***/.local/lib/python3.7/site-packages/sqlalchemy/sql/schema.py", line 4745, in create_all
[2022-10-05 21:31:29,024] {subprocess.py:92} INFO -     ddl.SchemaGenerator, self, checkfirst=checkfirst, tables=tables
[2022-10-05 21:31:29,024] {subprocess.py:92} INFO -   File "/home/***/.local/lib/python3.7/site-packages/sqlalchemy/engine/base.py", line 3007, in _run_ddl_visitor
[2022-10-05 21:31:29,024] {subprocess.py:92} INFO -     with self.begin() as conn:
[2022-10-05 21:31:29,024] {subprocess.py:92} INFO -   File "/home/***/.local/lib/python3.7/site-packages/sqlalchemy/engine/base.py", line 2923, in begin
[2022-10-05 21:31:29,024] {subprocess.py:92} INFO -     conn = self.connect(close_with_result=close_with_result)
[2022-10-05 21:31:29,024] {subprocess.py:92} INFO -   File "/home/***/.local/lib/python3.7/site-packages/sqlalchemy/engine/base.py", line 3095, in connect
[2022-10-05 21:31:29,024] {subprocess.py:92} INFO -     return self._connection_cls(self, close_with_result=close_with_result)
[2022-10-05 21:31:29,024] {subprocess.py:92} INFO -   File "/home/***/.local/lib/python3.7/site-packages/sqlalchemy/engine/base.py", line 91, in __init__
[2022-10-05 21:31:29,024] {subprocess.py:92} INFO -     else engine.raw_connection()
[2022-10-05 21:31:29,024] {subprocess.py:92} INFO -   File "/home/***/.local/lib/python3.7/site-packages/sqlalchemy/engine/base.py", line 3174, in raw_connection
[2022-10-05 21:31:29,024] {subprocess.py:92} INFO -     return self._wrap_pool_connect(self.pool.connect, _connection)
[2022-10-05 21:31:29,025] {subprocess.py:92} INFO -   File "/home/***/.local/lib/python3.7/site-packages/sqlalchemy/engine/base.py", line 3145, in _wrap_pool_connect
[2022-10-05 21:31:29,025] {subprocess.py:92} INFO -     e, dialect, self
[2022-10-05 21:31:29,025] {subprocess.py:92} INFO -   File "/home/***/.local/lib/python3.7/site-packages/sqlalchemy/engine/base.py", line 2004, in _handle_dbapi_exception_noconnection
[2022-10-05 21:31:29,025] {subprocess.py:92} INFO -     sqlalchemy_exception, with_traceback=exc_info[2], from_=e
[2022-10-05 21:31:29,025] {subprocess.py:92} INFO -   File "/home/***/.local/lib/python3.7/site-packages/sqlalchemy/util/compat.py", line 211, in raise_
[2022-10-05 21:31:29,025] {subprocess.py:92} INFO -     raise exception
[2022-10-05 21:31:29,025] {subprocess.py:92} INFO -   File "/home/***/.local/lib/python3.7/site-packages/sqlalchemy/engine/base.py", line 3141, in _wrap_pool_connect
[2022-10-05 21:31:29,025] {subprocess.py:92} INFO -     return fn()
[2022-10-05 21:31:29,025] {subprocess.py:92} INFO -   File "/home/***/.local/lib/python3.7/site-packages/sqlalchemy/pool/base.py", line 301, in connect
[2022-10-05 21:31:29,025] {subprocess.py:92} INFO -     return _ConnectionFairy._checkout(self)
[2022-10-05 21:31:29,025] {subprocess.py:92} INFO -   File "/home/***/.local/lib/python3.7/site-packages/sqlalchemy/pool/base.py", line 755, in _checkout
[2022-10-05 21:31:29,026] {subprocess.py:92} INFO -     fairy = _ConnectionRecord.checkout(pool)
[2022-10-05 21:31:29,026] {subprocess.py:92} INFO -   File "/home/***/.local/lib/python3.7/site-packages/sqlalchemy/pool/base.py", line 419, in checkout
[2022-10-05 21:31:29,026] {subprocess.py:92} INFO -     rec = pool._do_get()
[2022-10-05 21:31:29,026] {subprocess.py:92} INFO -   File "/home/***/.local/lib/python3.7/site-packages/sqlalchemy/pool/impl.py", line 145, in _do_get
[2022-10-05 21:31:29,026] {subprocess.py:92} INFO -     self._dec_overflow()
[2022-10-05 21:31:29,026] {subprocess.py:92} INFO -   File "/home/***/.local/lib/python3.7/site-packages/sqlalchemy/util/langhelpers.py", line 72, in __exit__
[2022-10-05 21:31:29,026] {subprocess.py:92} INFO -     with_traceback=exc_tb,
[2022-10-05 21:31:29,026] {subprocess.py:92} INFO -   File "/home/***/.local/lib/python3.7/site-packages/sqlalchemy/util/compat.py", line 211, in raise_
[2022-10-05 21:31:29,026] {subprocess.py:92} INFO -     raise exception
[2022-10-05 21:31:29,026] {subprocess.py:92} INFO -   File "/home/***/.local/lib/python3.7/site-packages/sqlalchemy/pool/impl.py", line 142, in _do_get
[2022-10-05 21:31:29,026] {subprocess.py:92} INFO -     return self._create_connection()
[2022-10-05 21:31:29,026] {subprocess.py:92} INFO -   File "/home/***/.local/lib/python3.7/site-packages/sqlalchemy/pool/base.py", line 247, in _create_connection
[2022-10-05 21:31:29,026] {subprocess.py:92} INFO -     return _ConnectionRecord(self)
[2022-10-05 21:31:29,026] {subprocess.py:92} INFO -   File "/home/***/.local/lib/python3.7/site-packages/sqlalchemy/pool/base.py", line 362, in __init__
[2022-10-05 21:31:29,026] {subprocess.py:92} INFO -     self.__connect(first_connect_check=True)
[2022-10-05 21:31:29,026] {subprocess.py:92} INFO -   File "/home/***/.local/lib/python3.7/site-packages/sqlalchemy/pool/base.py", line 605, in __connect
[2022-10-05 21:31:29,026] {subprocess.py:92} INFO -     pool.logger.debug("Error on connect(): %s", e)
[2022-10-05 21:31:29,026] {subprocess.py:92} INFO -   File "/home/***/.local/lib/python3.7/site-packages/sqlalchemy/util/langhelpers.py", line 72, in __exit__
[2022-10-05 21:31:29,026] {subprocess.py:92} INFO -     with_traceback=exc_tb,
[2022-10-05 21:31:29,026] {subprocess.py:92} INFO -   File "/home/***/.local/lib/python3.7/site-packages/sqlalchemy/util/compat.py", line 211, in raise_
[2022-10-05 21:31:29,026] {subprocess.py:92} INFO -     raise exception
[2022-10-05 21:31:29,026] {subprocess.py:92} INFO -   File "/home/***/.local/lib/python3.7/site-packages/sqlalchemy/pool/base.py", line 599, in __connect
[2022-10-05 21:31:29,026] {subprocess.py:92} INFO -     connection = pool._invoke_creator(self)
[2022-10-05 21:31:29,026] {subprocess.py:92} INFO -   File "/home/***/.local/lib/python3.7/site-packages/sqlalchemy/engine/create.py", line 578, in connect
[2022-10-05 21:31:29,026] {subprocess.py:92} INFO -     return dialect.connect(*cargs, **cparams)
[2022-10-05 21:31:29,026] {subprocess.py:92} INFO -   File "/home/***/.local/lib/python3.7/site-packages/sqlalchemy/engine/default.py", line 583, in connect
[2022-10-05 21:31:29,026] {subprocess.py:92} INFO -     return self.dbapi.connect(*cargs, **cparams)
[2022-10-05 21:31:29,026] {subprocess.py:92} INFO -   File "/home/***/.local/lib/python3.7/site-packages/psycopg2/__init__.py", line 122, in connect
[2022-10-05 21:31:29,026] {subprocess.py:92} INFO -     conn = _connect(dsn, connection_factory=connection_factory, **kwasync)
[2022-10-05 21:31:29,026] {subprocess.py:92} INFO - sqlalchemy.exc.OperationalError: (psycopg2.OperationalError) connection to server at "127.0.0.1", port 5432 failed: Connection refused
[2022-10-05 21:31:29,027] {subprocess.py:92} INFO - 	Is the server running on that host and accepting TCP/IP connections?
[2022-10-05 21:31:29,027] {subprocess.py:92} INFO - 
[2022-10-05 21:31:29,027] {subprocess.py:92} INFO - (Background on this error at: http://sqlalche.me/e/14/e3q8)
[2022-10-05 21:31:29,290] {subprocess.py:96} INFO - Command exited with return code 1
[2022-10-05 21:31:29,917] {taskinstance.py:1889} ERROR - Task failed with exception
Traceback (most recent call last):
  File "/home/airflow/.local/lib/python3.7/site-packages/airflow/operators/bash.py", line 195, in execute
    f'Bash command failed. The command returned a non-zero exit code {result.exit_code}.'
airflow.exceptions.AirflowException: Bash command failed. The command returned a non-zero exit code 1.
[2022-10-05 21:31:29,965] {taskinstance.py:1400} INFO - Marking task as FAILED. dag_id=load_rappers_dag, task_id=load_rappers, execution_date=20221005T200000, start_date=20221005T212632, end_date=20221005T213129
[2022-10-05 21:31:30,144] {standard_task_runner.py:97} ERROR - Failed to execute job 38 for task load_rappers (Bash command failed. The command returned a non-zero exit code 1.; 3252)
[2022-10-05 21:31:30,226] {local_task_job.py:156} INFO - Task exited with return code 1
[2022-10-05 21:31:30,415] {local_task_job.py:273} INFO - 0 downstream tasks scheduled from follow-on schedule check
[2022-10-07 17:19:02,114] {taskinstance.py:1159} INFO - Dependencies all met for <TaskInstance: load_rappers_dag.load_rappers scheduled__2022-10-05T20:00:00+00:00 [queued]>
[2022-10-07 17:19:02,153] {taskinstance.py:1159} INFO - Dependencies all met for <TaskInstance: load_rappers_dag.load_rappers scheduled__2022-10-05T20:00:00+00:00 [queued]>
[2022-10-07 17:19:02,153] {taskinstance.py:1356} INFO - 
--------------------------------------------------------------------------------
[2022-10-07 17:19:02,153] {taskinstance.py:1357} INFO - Starting attempt 1 of 1
[2022-10-07 17:19:02,153] {taskinstance.py:1358} INFO - 
--------------------------------------------------------------------------------
[2022-10-07 17:19:02,192] {taskinstance.py:1377} INFO - Executing <Task(BashOperator): load_rappers> on 2022-10-05 20:00:00+00:00
[2022-10-07 17:19:02,197] {standard_task_runner.py:52} INFO - Started process 1745 to run task
[2022-10-07 17:19:02,211] {standard_task_runner.py:79} INFO - Running: ['***', 'tasks', 'run', 'load_rappers_dag', 'load_rappers', 'scheduled__2022-10-05T20:00:00+00:00', '--job-id', '23', '--raw', '--subdir', 'DAGS_FOLDER/load_rappers_dag.py', '--cfg-path', '/tmp/tmpu1zypex_', '--error-file', '/tmp/tmpy1cp8yt3']
[2022-10-07 17:19:02,215] {standard_task_runner.py:80} INFO - Job 23: Subtask load_rappers
[2022-10-07 17:19:02,294] {task_command.py:369} INFO - Running <TaskInstance: load_rappers_dag.load_rappers scheduled__2022-10-05T20:00:00+00:00 [running]> on host 84650b6b2dfc
[2022-10-07 17:19:02,511] {taskinstance.py:1571} INFO - Exporting the following env vars:
AIRFLOW_CTX_DAG_OWNER=***
AIRFLOW_CTX_DAG_ID=load_rappers_dag
AIRFLOW_CTX_TASK_ID=load_rappers
AIRFLOW_CTX_EXECUTION_DATE=2022-10-05T20:00:00+00:00
AIRFLOW_CTX_TRY_NUMBER=1
AIRFLOW_CTX_DAG_RUN_ID=scheduled__2022-10-05T20:00:00+00:00
[2022-10-07 17:19:02,512] {subprocess.py:62} INFO - Tmp dir root location: 
 /tmp
[2022-10-07 17:19:02,513] {subprocess.py:74} INFO - Running command: ['bash', '-c', 'python ${AIRFLOW_HOME}/scripts/load_rappers.py']
[2022-10-07 17:19:02,529] {subprocess.py:85} INFO - Output:
[2022-10-07 17:19:09,422] {subprocess.py:92} INFO - Compiling artist list...
[2022-10-07 17:19:09,423] {subprocess.py:92} INFO - Traceback (most recent call last):
[2022-10-07 17:19:09,423] {subprocess.py:92} INFO -   File "/opt/***/scripts/load_rappers.py", line 82, in <module>
[2022-10-07 17:19:09,423] {subprocess.py:92} INFO -     main()
[2022-10-07 17:19:09,423] {subprocess.py:92} INFO -   File "/opt/***/scripts/load_rappers.py", line 73, in main
[2022-10-07 17:19:09,423] {subprocess.py:92} INFO -     combinedArtists = compile_artists(lister, genreDict, playlistDict)
[2022-10-07 17:19:09,424] {subprocess.py:92} INFO -   File "/opt/***/scripts/load_rappers.py", line 38, in compile_artists
[2022-10-07 17:19:09,424] {subprocess.py:92} INFO -     return lister.combine_artists(genreDict, playlistDict)
[2022-10-07 17:19:09,424] {subprocess.py:92} INFO -   File "/opt/***/scripts/artist_lister.py", line 38, in combine_artists
[2022-10-07 17:19:09,424] {subprocess.py:92} INFO -     artistDict = self.union_dict(artistDict, self.parse_search(k, v))
[2022-10-07 17:19:09,424] {subprocess.py:92} INFO -   File "/opt/***/scripts/artist_lister.py", line 16, in parse_search
[2022-10-07 17:19:09,424] {subprocess.py:92} INFO -     for i in range(len(payload['artists']['items'])):
[2022-10-07 17:19:09,424] {subprocess.py:92} INFO - KeyError: 'artists'
[2022-10-07 17:19:09,726] {subprocess.py:96} INFO - Command exited with return code 1
[2022-10-07 17:19:09,769] {taskinstance.py:1889} ERROR - Task failed with exception
Traceback (most recent call last):
  File "/home/airflow/.local/lib/python3.7/site-packages/airflow/operators/bash.py", line 195, in execute
    f'Bash command failed. The command returned a non-zero exit code {result.exit_code}.'
airflow.exceptions.AirflowException: Bash command failed. The command returned a non-zero exit code 1.
[2022-10-07 17:19:09,777] {taskinstance.py:1400} INFO - Marking task as FAILED. dag_id=load_rappers_dag, task_id=load_rappers, execution_date=20221005T200000, start_date=20221007T171902, end_date=20221007T171909
[2022-10-07 17:19:09,820] {standard_task_runner.py:97} ERROR - Failed to execute job 23 for task load_rappers (Bash command failed. The command returned a non-zero exit code 1.; 1745)
[2022-10-07 17:19:09,833] {local_task_job.py:156} INFO - Task exited with return code 1
[2022-10-07 17:19:09,906] {local_task_job.py:273} INFO - 0 downstream tasks scheduled from follow-on schedule check
