[2022-10-07 17:21:41,263] {taskinstance.py:1159} INFO - Dependencies all met for <TaskInstance: load_rappers_dag.load_rappers scheduled__2022-10-07T02:00:00+00:00 [queued]>
[2022-10-07 17:21:41,296] {taskinstance.py:1159} INFO - Dependencies all met for <TaskInstance: load_rappers_dag.load_rappers scheduled__2022-10-07T02:00:00+00:00 [queued]>
[2022-10-07 17:21:41,296] {taskinstance.py:1356} INFO - 
--------------------------------------------------------------------------------
[2022-10-07 17:21:41,296] {taskinstance.py:1357} INFO - Starting attempt 1 of 1
[2022-10-07 17:21:41,296] {taskinstance.py:1358} INFO - 
--------------------------------------------------------------------------------
[2022-10-07 17:21:41,343] {taskinstance.py:1377} INFO - Executing <Task(BashOperator): load_rappers> on 2022-10-07 02:00:00+00:00
[2022-10-07 17:21:41,359] {standard_task_runner.py:52} INFO - Started process 2207 to run task
[2022-10-07 17:21:41,366] {standard_task_runner.py:79} INFO - Running: ['***', 'tasks', 'run', 'load_rappers_dag', 'load_rappers', 'scheduled__2022-10-07T02:00:00+00:00', '--job-id', '53', '--raw', '--subdir', 'DAGS_FOLDER/load_rappers_dag.py', '--cfg-path', '/tmp/tmpccyxitfg', '--error-file', '/tmp/tmpyk3jx29y']
[2022-10-07 17:21:41,368] {standard_task_runner.py:80} INFO - Job 53: Subtask load_rappers
[2022-10-07 17:21:41,628] {task_command.py:369} INFO - Running <TaskInstance: load_rappers_dag.load_rappers scheduled__2022-10-07T02:00:00+00:00 [running]> on host 84650b6b2dfc
[2022-10-07 17:21:41,925] {taskinstance.py:1571} INFO - Exporting the following env vars:
AIRFLOW_CTX_DAG_OWNER=***
AIRFLOW_CTX_DAG_ID=load_rappers_dag
AIRFLOW_CTX_TASK_ID=load_rappers
AIRFLOW_CTX_EXECUTION_DATE=2022-10-07T02:00:00+00:00
AIRFLOW_CTX_TRY_NUMBER=1
AIRFLOW_CTX_DAG_RUN_ID=scheduled__2022-10-07T02:00:00+00:00
[2022-10-07 17:21:41,930] {subprocess.py:62} INFO - Tmp dir root location: 
 /tmp
[2022-10-07 17:21:41,933] {subprocess.py:74} INFO - Running command: ['bash', '-c', 'python ${AIRFLOW_HOME}/scripts/load_rappers.py']
[2022-10-07 17:21:41,986] {subprocess.py:85} INFO - Output:
[2022-10-07 17:22:30,753] {subprocess.py:92} INFO - Compiling artist list...
[2022-10-07 17:22:31,132] {subprocess.py:92} INFO - Traceback (most recent call last):
[2022-10-07 17:22:31,132] {subprocess.py:92} INFO -   File "/home/***/.local/lib/python3.7/site-packages/urllib3/connectionpool.py", line 710, in urlopen
[2022-10-07 17:22:31,133] {subprocess.py:92} INFO -     chunked=chunked,
[2022-10-07 17:22:31,133] {subprocess.py:92} INFO -   File "/home/***/.local/lib/python3.7/site-packages/urllib3/connectionpool.py", line 386, in _make_request
[2022-10-07 17:22:31,133] {subprocess.py:92} INFO -     self._validate_conn(conn)
[2022-10-07 17:22:31,133] {subprocess.py:92} INFO -   File "/home/***/.local/lib/python3.7/site-packages/urllib3/connectionpool.py", line 1040, in _validate_conn
[2022-10-07 17:22:31,133] {subprocess.py:92} INFO -     conn.connect()
[2022-10-07 17:22:31,133] {subprocess.py:92} INFO -   File "/home/***/.local/lib/python3.7/site-packages/urllib3/connection.py", line 424, in connect
[2022-10-07 17:22:31,133] {subprocess.py:92} INFO -     tls_in_tls=tls_in_tls,
[2022-10-07 17:22:31,133] {subprocess.py:92} INFO -   File "/home/***/.local/lib/python3.7/site-packages/urllib3/util/ssl_.py", line 450, in ssl_wrap_socket
[2022-10-07 17:22:31,133] {subprocess.py:92} INFO -     sock, context, tls_in_tls, server_hostname=server_hostname
[2022-10-07 17:22:31,134] {subprocess.py:92} INFO -   File "/home/***/.local/lib/python3.7/site-packages/urllib3/util/ssl_.py", line 493, in _ssl_wrap_socket_impl
[2022-10-07 17:22:31,134] {subprocess.py:92} INFO -     return ssl_context.wrap_socket(sock, server_hostname=server_hostname)
[2022-10-07 17:22:31,134] {subprocess.py:92} INFO -   File "/usr/local/lib/python3.7/ssl.py", line 423, in wrap_socket
[2022-10-07 17:22:31,134] {subprocess.py:92} INFO -     session=session
[2022-10-07 17:22:31,134] {subprocess.py:92} INFO -   File "/usr/local/lib/python3.7/ssl.py", line 870, in _create
[2022-10-07 17:22:31,134] {subprocess.py:92} INFO -     self.do_handshake()
[2022-10-07 17:22:31,134] {subprocess.py:92} INFO -   File "/usr/local/lib/python3.7/ssl.py", line 1139, in do_handshake
[2022-10-07 17:22:31,134] {subprocess.py:92} INFO -     self._sslobj.do_handshake()
[2022-10-07 17:22:31,135] {subprocess.py:92} INFO - OSError: [Errno 0] Error
[2022-10-07 17:22:31,135] {subprocess.py:92} INFO - 
[2022-10-07 17:22:31,135] {subprocess.py:92} INFO - During handling of the above exception, another exception occurred:
[2022-10-07 17:22:31,135] {subprocess.py:92} INFO - 
[2022-10-07 17:22:31,135] {subprocess.py:92} INFO - Traceback (most recent call last):
[2022-10-07 17:22:31,135] {subprocess.py:92} INFO -   File "/home/***/.local/lib/python3.7/site-packages/requests/adapters.py", line 450, in send
[2022-10-07 17:22:31,135] {subprocess.py:92} INFO -     timeout=timeout
[2022-10-07 17:22:31,135] {subprocess.py:92} INFO -   File "/home/***/.local/lib/python3.7/site-packages/urllib3/connectionpool.py", line 786, in urlopen
[2022-10-07 17:22:31,135] {subprocess.py:92} INFO -     method, url, error=e, _pool=self, _stacktrace=sys.exc_info()[2]
[2022-10-07 17:22:31,135] {subprocess.py:92} INFO -   File "/home/***/.local/lib/python3.7/site-packages/urllib3/util/retry.py", line 550, in increment
[2022-10-07 17:22:31,136] {subprocess.py:92} INFO -     raise six.reraise(type(error), error, _stacktrace)
[2022-10-07 17:22:31,136] {subprocess.py:92} INFO -   File "/home/***/.local/lib/python3.7/site-packages/urllib3/packages/six.py", line 769, in reraise
[2022-10-07 17:22:31,136] {subprocess.py:92} INFO -     raise value.with_traceback(tb)
[2022-10-07 17:22:31,136] {subprocess.py:92} INFO -   File "/home/***/.local/lib/python3.7/site-packages/urllib3/connectionpool.py", line 710, in urlopen
[2022-10-07 17:22:31,136] {subprocess.py:92} INFO -     chunked=chunked,
[2022-10-07 17:22:31,136] {subprocess.py:92} INFO -   File "/home/***/.local/lib/python3.7/site-packages/urllib3/connectionpool.py", line 386, in _make_request
[2022-10-07 17:22:31,136] {subprocess.py:92} INFO -     self._validate_conn(conn)
[2022-10-07 17:22:31,136] {subprocess.py:92} INFO -   File "/home/***/.local/lib/python3.7/site-packages/urllib3/connectionpool.py", line 1040, in _validate_conn
[2022-10-07 17:22:31,136] {subprocess.py:92} INFO -     conn.connect()
[2022-10-07 17:22:31,136] {subprocess.py:92} INFO -   File "/home/***/.local/lib/python3.7/site-packages/urllib3/connection.py", line 424, in connect
[2022-10-07 17:22:31,137] {subprocess.py:92} INFO -     tls_in_tls=tls_in_tls,
[2022-10-07 17:22:31,137] {subprocess.py:92} INFO -   File "/home/***/.local/lib/python3.7/site-packages/urllib3/util/ssl_.py", line 450, in ssl_wrap_socket
[2022-10-07 17:22:31,137] {subprocess.py:92} INFO -     sock, context, tls_in_tls, server_hostname=server_hostname
[2022-10-07 17:22:31,137] {subprocess.py:92} INFO -   File "/home/***/.local/lib/python3.7/site-packages/urllib3/util/ssl_.py", line 493, in _ssl_wrap_socket_impl
[2022-10-07 17:22:31,137] {subprocess.py:92} INFO -     return ssl_context.wrap_socket(sock, server_hostname=server_hostname)
[2022-10-07 17:22:31,137] {subprocess.py:92} INFO -   File "/usr/local/lib/python3.7/ssl.py", line 423, in wrap_socket
[2022-10-07 17:22:31,137] {subprocess.py:92} INFO -     session=session
[2022-10-07 17:22:31,137] {subprocess.py:92} INFO -   File "/usr/local/lib/python3.7/ssl.py", line 870, in _create
[2022-10-07 17:22:31,137] {subprocess.py:92} INFO -     self.do_handshake()
[2022-10-07 17:22:31,138] {subprocess.py:92} INFO -   File "/usr/local/lib/python3.7/ssl.py", line 1139, in do_handshake
[2022-10-07 17:22:31,138] {subprocess.py:92} INFO -     self._sslobj.do_handshake()
[2022-10-07 17:22:31,138] {subprocess.py:92} INFO - urllib3.exceptions.ProtocolError: ('Connection aborted.', OSError(0, 'Error'))
[2022-10-07 17:22:31,138] {subprocess.py:92} INFO - 
[2022-10-07 17:22:31,138] {subprocess.py:92} INFO - During handling of the above exception, another exception occurred:
[2022-10-07 17:22:31,138] {subprocess.py:92} INFO - 
[2022-10-07 17:22:31,138] {subprocess.py:92} INFO - Traceback (most recent call last):
[2022-10-07 17:22:31,138] {subprocess.py:92} INFO -   File "/opt/***/scripts/load_rappers.py", line 82, in <module>
[2022-10-07 17:22:31,138] {subprocess.py:92} INFO -     main()
[2022-10-07 17:22:31,138] {subprocess.py:92} INFO -   File "/opt/***/scripts/load_rappers.py", line 73, in main
[2022-10-07 17:22:31,139] {subprocess.py:92} INFO -     combinedArtists = compile_artists(lister, genreDict, playlistDict)
[2022-10-07 17:22:31,139] {subprocess.py:92} INFO -   File "/opt/***/scripts/load_rappers.py", line 38, in compile_artists
[2022-10-07 17:22:31,139] {subprocess.py:92} INFO -     return lister.combine_artists(genreDict, playlistDict)
[2022-10-07 17:22:31,139] {subprocess.py:92} INFO -   File "/opt/***/scripts/artist_lister.py", line 40, in combine_artists
[2022-10-07 17:22:31,139] {subprocess.py:92} INFO -     artistDict = self.union_dict(artistDict, self.parse_playlist(k))
[2022-10-07 17:22:31,139] {subprocess.py:92} INFO -   File "/opt/***/scripts/artist_lister.py", line 24, in parse_playlist
[2022-10-07 17:22:31,139] {subprocess.py:92} INFO -     payload = self.get_playlist_artists(playlist_id, limit=min(rows, 50), offset=batch)
[2022-10-07 17:22:31,139] {subprocess.py:92} INFO -   File "/opt/***/scripts/spotify_client.py", line 108, in get_playlist_artists
[2022-10-07 17:22:31,139] {subprocess.py:92} INFO -     return self.get_resource(_id, resource_type='playlists', query_postfix=f'tracks?fields=items(track(artists(id, name)))&limit={limit}&offset={offset}')
[2022-10-07 17:22:31,139] {subprocess.py:92} INFO -   File "/opt/***/scripts/spotify_client.py", line 81, in get_resource
[2022-10-07 17:22:31,139] {subprocess.py:92} INFO -     r = requests.get(endpoint, headers=headers)
[2022-10-07 17:22:31,139] {subprocess.py:92} INFO -   File "/home/***/.local/lib/python3.7/site-packages/requests/api.py", line 75, in get
[2022-10-07 17:22:31,140] {subprocess.py:92} INFO -     return request('get', url, params=params, **kwargs)
[2022-10-07 17:22:31,140] {subprocess.py:92} INFO -   File "/home/***/.local/lib/python3.7/site-packages/requests/api.py", line 61, in request
[2022-10-07 17:22:31,140] {subprocess.py:92} INFO -     return session.request(method=method, url=url, **kwargs)
[2022-10-07 17:22:31,140] {subprocess.py:92} INFO -   File "/home/***/.local/lib/python3.7/site-packages/requests/sessions.py", line 529, in request
[2022-10-07 17:22:31,140] {subprocess.py:92} INFO -     resp = self.send(prep, **send_kwargs)
[2022-10-07 17:22:31,140] {subprocess.py:92} INFO -   File "/home/***/.local/lib/python3.7/site-packages/requests/sessions.py", line 645, in send
[2022-10-07 17:22:31,140] {subprocess.py:92} INFO -     r = adapter.send(request, **kwargs)
[2022-10-07 17:22:31,140] {subprocess.py:92} INFO -   File "/home/***/.local/lib/python3.7/site-packages/requests/adapters.py", line 501, in send
[2022-10-07 17:22:31,140] {subprocess.py:92} INFO -     raise ConnectionError(err, request=request)
[2022-10-07 17:22:31,140] {subprocess.py:92} INFO - requests.exceptions.ConnectionError: ('Connection aborted.', OSError(0, 'Error'))
[2022-10-07 17:22:32,618] {subprocess.py:96} INFO - Command exited with return code 1
[2022-10-07 17:22:33,105] {taskinstance.py:1889} ERROR - Task failed with exception
Traceback (most recent call last):
  File "/home/airflow/.local/lib/python3.7/site-packages/airflow/operators/bash.py", line 195, in execute
    f'Bash command failed. The command returned a non-zero exit code {result.exit_code}.'
airflow.exceptions.AirflowException: Bash command failed. The command returned a non-zero exit code 1.
[2022-10-07 17:22:33,204] {taskinstance.py:1400} INFO - Marking task as FAILED. dag_id=load_rappers_dag, task_id=load_rappers, execution_date=20221007T020000, start_date=20221007T172141, end_date=20221007T172233
[2022-10-07 17:22:33,780] {standard_task_runner.py:97} ERROR - Failed to execute job 53 for task load_rappers (Bash command failed. The command returned a non-zero exit code 1.; 2207)
[2022-10-07 17:22:34,062] {local_task_job.py:156} INFO - Task exited with return code 1
[2022-10-07 17:22:34,727] {local_task_job.py:273} INFO - 0 downstream tasks scheduled from follow-on schedule check
