[2022-10-07 17:23:07,454] {taskinstance.py:1159} INFO - Dependencies all met for <TaskInstance: load_rappers_dag.load_rappers scheduled__2022-10-07T09:00:00+00:00 [queued]>
[2022-10-07 17:23:07,517] {taskinstance.py:1159} INFO - Dependencies all met for <TaskInstance: load_rappers_dag.load_rappers scheduled__2022-10-07T09:00:00+00:00 [queued]>
[2022-10-07 17:23:07,517] {taskinstance.py:1356} INFO - 
--------------------------------------------------------------------------------
[2022-10-07 17:23:07,517] {taskinstance.py:1357} INFO - Starting attempt 1 of 1
[2022-10-07 17:23:07,517] {taskinstance.py:1358} INFO - 
--------------------------------------------------------------------------------
[2022-10-07 17:23:07,645] {taskinstance.py:1377} INFO - Executing <Task(BashOperator): load_rappers> on 2022-10-07 09:00:00+00:00
[2022-10-07 17:23:07,658] {standard_task_runner.py:52} INFO - Started process 2297 to run task
[2022-10-07 17:23:07,673] {standard_task_runner.py:79} INFO - Running: ['***', 'tasks', 'run', 'load_rappers_dag', 'load_rappers', 'scheduled__2022-10-07T09:00:00+00:00', '--job-id', '57', '--raw', '--subdir', 'DAGS_FOLDER/load_rappers_dag.py', '--cfg-path', '/tmp/tmpu0vr68ol', '--error-file', '/tmp/tmpv8r42l6v']
[2022-10-07 17:23:07,679] {standard_task_runner.py:80} INFO - Job 57: Subtask load_rappers
[2022-10-07 17:23:08,010] {task_command.py:369} INFO - Running <TaskInstance: load_rappers_dag.load_rappers scheduled__2022-10-07T09:00:00+00:00 [running]> on host 84650b6b2dfc
[2022-10-07 17:23:08,465] {taskinstance.py:1571} INFO - Exporting the following env vars:
AIRFLOW_CTX_DAG_OWNER=***
AIRFLOW_CTX_DAG_ID=load_rappers_dag
AIRFLOW_CTX_TASK_ID=load_rappers
AIRFLOW_CTX_EXECUTION_DATE=2022-10-07T09:00:00+00:00
AIRFLOW_CTX_TRY_NUMBER=1
AIRFLOW_CTX_DAG_RUN_ID=scheduled__2022-10-07T09:00:00+00:00
[2022-10-07 17:23:08,472] {subprocess.py:62} INFO - Tmp dir root location: 
 /tmp
[2022-10-07 17:23:08,477] {subprocess.py:74} INFO - Running command: ['bash', '-c', 'python ${AIRFLOW_HOME}/scripts/load_rappers.py']
[2022-10-07 17:23:08,549] {subprocess.py:85} INFO - Output:
[2022-10-07 17:23:43,235] {subprocess.py:92} INFO - Compiling artist list...
[2022-10-07 17:23:48,993] {subprocess.py:92} INFO - Traceback (most recent call last):
[2022-10-07 17:23:49,005] {subprocess.py:92} INFO -   File "/home/***/.local/lib/python3.7/site-packages/urllib3/connection.py", line 175, in _new_conn
[2022-10-07 17:23:49,006] {subprocess.py:92} INFO -     (self._dns_host, self.port), self.timeout, **extra_kw
[2022-10-07 17:23:49,006] {subprocess.py:92} INFO -   File "/home/***/.local/lib/python3.7/site-packages/urllib3/util/connection.py", line 72, in create_connection
[2022-10-07 17:23:49,006] {subprocess.py:92} INFO -     for res in socket.getaddrinfo(host, port, family, socket.SOCK_STREAM):
[2022-10-07 17:23:49,006] {subprocess.py:92} INFO -   File "/usr/local/lib/python3.7/socket.py", line 752, in getaddrinfo
[2022-10-07 17:23:49,006] {subprocess.py:92} INFO -     for res in _socket.getaddrinfo(host, port, family, type, proto, flags):
[2022-10-07 17:23:49,006] {subprocess.py:92} INFO - socket.gaierror: [Errno -3] Temporary failure in name resolution
[2022-10-07 17:23:49,006] {subprocess.py:92} INFO - 
[2022-10-07 17:23:49,006] {subprocess.py:92} INFO - During handling of the above exception, another exception occurred:
[2022-10-07 17:23:49,007] {subprocess.py:92} INFO - 
[2022-10-07 17:23:49,007] {subprocess.py:92} INFO - Traceback (most recent call last):
[2022-10-07 17:23:49,007] {subprocess.py:92} INFO -   File "/home/***/.local/lib/python3.7/site-packages/urllib3/connectionpool.py", line 710, in urlopen
[2022-10-07 17:23:49,007] {subprocess.py:92} INFO -     chunked=chunked,
[2022-10-07 17:23:49,007] {subprocess.py:92} INFO -   File "/home/***/.local/lib/python3.7/site-packages/urllib3/connectionpool.py", line 386, in _make_request
[2022-10-07 17:23:49,007] {subprocess.py:92} INFO -     self._validate_conn(conn)
[2022-10-07 17:23:49,007] {subprocess.py:92} INFO -   File "/home/***/.local/lib/python3.7/site-packages/urllib3/connectionpool.py", line 1040, in _validate_conn
[2022-10-07 17:23:49,007] {subprocess.py:92} INFO -     conn.connect()
[2022-10-07 17:23:49,007] {subprocess.py:92} INFO -   File "/home/***/.local/lib/python3.7/site-packages/urllib3/connection.py", line 358, in connect
[2022-10-07 17:23:49,007] {subprocess.py:92} INFO -     self.sock = conn = self._new_conn()
[2022-10-07 17:23:49,011] {subprocess.py:92} INFO -   File "/home/***/.local/lib/python3.7/site-packages/urllib3/connection.py", line 187, in _new_conn
[2022-10-07 17:23:49,012] {subprocess.py:92} INFO -     self, "Failed to establish a new connection: %s" % e
[2022-10-07 17:23:49,012] {subprocess.py:92} INFO - urllib3.exceptions.NewConnectionError: <urllib3.connection.HTTPSConnection object at 0x7f945b6c0350>: Failed to establish a new connection: [Errno -3] Temporary failure in name resolution
[2022-10-07 17:23:49,034] {subprocess.py:92} INFO - 
[2022-10-07 17:23:49,034] {subprocess.py:92} INFO - During handling of the above exception, another exception occurred:
[2022-10-07 17:23:49,035] {subprocess.py:92} INFO - 
[2022-10-07 17:23:49,035] {subprocess.py:92} INFO - Traceback (most recent call last):
[2022-10-07 17:23:49,035] {subprocess.py:92} INFO -   File "/home/***/.local/lib/python3.7/site-packages/requests/adapters.py", line 450, in send
[2022-10-07 17:23:49,035] {subprocess.py:92} INFO -     timeout=timeout
[2022-10-07 17:23:49,035] {subprocess.py:92} INFO -   File "/home/***/.local/lib/python3.7/site-packages/urllib3/connectionpool.py", line 786, in urlopen
[2022-10-07 17:23:49,035] {subprocess.py:92} INFO -     method, url, error=e, _pool=self, _stacktrace=sys.exc_info()[2]
[2022-10-07 17:23:49,035] {subprocess.py:92} INFO -   File "/home/***/.local/lib/python3.7/site-packages/urllib3/util/retry.py", line 592, in increment
[2022-10-07 17:23:49,035] {subprocess.py:92} INFO -     raise MaxRetryError(_pool, url, error or ResponseError(cause))
[2022-10-07 17:23:49,035] {subprocess.py:92} INFO - urllib3.exceptions.MaxRetryError: HTTPSConnectionPool(host='api.spotify.com', port=443): Max retries exceeded with url: /v1/playlists/37i9dQZF1DX0XUsuxWHRQd/tracks?fields=items(track(artists(id,%20name)))&limit=50&offset=0 (Caused by NewConnectionError('<urllib3.connection.HTTPSConnection object at 0x7f945b6c0350>: Failed to establish a new connection: [Errno -3] Temporary failure in name resolution'))
[2022-10-07 17:23:49,035] {subprocess.py:92} INFO - 
[2022-10-07 17:23:49,036] {subprocess.py:92} INFO - During handling of the above exception, another exception occurred:
[2022-10-07 17:23:49,036] {subprocess.py:92} INFO - 
[2022-10-07 17:23:49,036] {subprocess.py:92} INFO - Traceback (most recent call last):
[2022-10-07 17:23:49,036] {subprocess.py:92} INFO -   File "/opt/***/scripts/load_rappers.py", line 82, in <module>
[2022-10-07 17:23:49,036] {subprocess.py:92} INFO -     main()
[2022-10-07 17:23:49,036] {subprocess.py:92} INFO -   File "/opt/***/scripts/load_rappers.py", line 73, in main
[2022-10-07 17:23:49,036] {subprocess.py:92} INFO -     combinedArtists = compile_artists(lister, genreDict, playlistDict)
[2022-10-07 17:23:49,036] {subprocess.py:92} INFO -   File "/opt/***/scripts/load_rappers.py", line 38, in compile_artists
[2022-10-07 17:23:49,036] {subprocess.py:92} INFO -     return lister.combine_artists(genreDict, playlistDict)
[2022-10-07 17:23:49,050] {subprocess.py:92} INFO -   File "/opt/***/scripts/artist_lister.py", line 40, in combine_artists
[2022-10-07 17:23:49,053] {subprocess.py:92} INFO -     artistDict = self.union_dict(artistDict, self.parse_playlist(k))
[2022-10-07 17:23:49,053] {subprocess.py:92} INFO -   File "/opt/***/scripts/artist_lister.py", line 24, in parse_playlist
[2022-10-07 17:23:49,053] {subprocess.py:92} INFO -     payload = self.get_playlist_artists(playlist_id, limit=min(rows, 50), offset=batch)
[2022-10-07 17:23:49,053] {subprocess.py:92} INFO -   File "/opt/***/scripts/spotify_client.py", line 108, in get_playlist_artists
[2022-10-07 17:23:49,053] {subprocess.py:92} INFO -     return self.get_resource(_id, resource_type='playlists', query_postfix=f'tracks?fields=items(track(artists(id, name)))&limit={limit}&offset={offset}')
[2022-10-07 17:23:49,053] {subprocess.py:92} INFO -   File "/opt/***/scripts/spotify_client.py", line 81, in get_resource
[2022-10-07 17:23:49,053] {subprocess.py:92} INFO -     r = requests.get(endpoint, headers=headers)
[2022-10-07 17:23:49,053] {subprocess.py:92} INFO -   File "/home/***/.local/lib/python3.7/site-packages/requests/api.py", line 75, in get
[2022-10-07 17:23:49,053] {subprocess.py:92} INFO -     return request('get', url, params=params, **kwargs)
[2022-10-07 17:23:49,054] {subprocess.py:92} INFO -   File "/home/***/.local/lib/python3.7/site-packages/requests/api.py", line 61, in request
[2022-10-07 17:23:49,054] {subprocess.py:92} INFO -     return session.request(method=method, url=url, **kwargs)
[2022-10-07 17:23:49,054] {subprocess.py:92} INFO -   File "/home/***/.local/lib/python3.7/site-packages/requests/sessions.py", line 529, in request
[2022-10-07 17:23:49,054] {subprocess.py:92} INFO -     resp = self.send(prep, **send_kwargs)
[2022-10-07 17:23:49,054] {subprocess.py:92} INFO -   File "/home/***/.local/lib/python3.7/site-packages/requests/sessions.py", line 645, in send
[2022-10-07 17:23:49,054] {subprocess.py:92} INFO -     r = adapter.send(request, **kwargs)
[2022-10-07 17:23:49,054] {subprocess.py:92} INFO -   File "/home/***/.local/lib/python3.7/site-packages/requests/adapters.py", line 519, in send
[2022-10-07 17:23:49,054] {subprocess.py:92} INFO -     raise ConnectionError(e, request=request)
[2022-10-07 17:23:49,070] {subprocess.py:92} INFO - requests.exceptions.ConnectionError: HTTPSConnectionPool(host='api.spotify.com', port=443): Max retries exceeded with url: /v1/playlists/37i9dQZF1DX0XUsuxWHRQd/tracks?fields=items(track(artists(id,%20name)))&limit=50&offset=0 (Caused by NewConnectionError('<urllib3.connection.HTTPSConnection object at 0x7f945b6c0350>: Failed to establish a new connection: [Errno -3] Temporary failure in name resolution'))
[2022-10-07 17:23:51,095] {subprocess.py:96} INFO - Command exited with return code 1
[2022-10-07 17:23:51,317] {taskinstance.py:1889} ERROR - Task failed with exception
Traceback (most recent call last):
  File "/home/airflow/.local/lib/python3.7/site-packages/airflow/operators/bash.py", line 195, in execute
    f'Bash command failed. The command returned a non-zero exit code {result.exit_code}.'
airflow.exceptions.AirflowException: Bash command failed. The command returned a non-zero exit code 1.
[2022-10-07 17:23:51,354] {taskinstance.py:1400} INFO - Marking task as FAILED. dag_id=load_rappers_dag, task_id=load_rappers, execution_date=20221007T090000, start_date=20221007T172307, end_date=20221007T172351
[2022-10-07 17:23:51,512] {standard_task_runner.py:97} ERROR - Failed to execute job 57 for task load_rappers (Bash command failed. The command returned a non-zero exit code 1.; 2297)
[2022-10-07 17:23:51,557] {local_task_job.py:156} INFO - Task exited with return code 1
[2022-10-07 17:23:51,864] {local_task_job.py:273} INFO - 0 downstream tasks scheduled from follow-on schedule check
