[2022-10-05 19:00:02,545] {taskinstance.py:1159} INFO - Dependencies all met for <TaskInstance: load_rappers_dag.load_rappers scheduled__2022-10-05T18:00:00+00:00 [queued]>
[2022-10-05 19:00:02,565] {taskinstance.py:1159} INFO - Dependencies all met for <TaskInstance: load_rappers_dag.load_rappers scheduled__2022-10-05T18:00:00+00:00 [queued]>
[2022-10-05 19:00:02,565] {taskinstance.py:1356} INFO - 
--------------------------------------------------------------------------------
[2022-10-05 19:00:02,565] {taskinstance.py:1357} INFO - Starting attempt 1 of 1
[2022-10-05 19:00:02,565] {taskinstance.py:1358} INFO - 
--------------------------------------------------------------------------------
[2022-10-05 19:00:02,585] {taskinstance.py:1377} INFO - Executing <Task(BashOperator): load_rappers> on 2022-10-05 18:00:00+00:00
[2022-10-05 19:00:02,590] {standard_task_runner.py:52} INFO - Started process 1032 to run task
[2022-10-05 19:00:02,600] {standard_task_runner.py:79} INFO - Running: ['***', 'tasks', 'run', 'load_rappers_dag', 'load_rappers', 'scheduled__2022-10-05T18:00:00+00:00', '--job-id', '32', '--raw', '--subdir', 'DAGS_FOLDER/load_rappers_dag.py', '--cfg-path', '/tmp/tmp0e04tggq', '--error-file', '/tmp/tmp1nmcb5c0']
[2022-10-05 19:00:02,604] {standard_task_runner.py:80} INFO - Job 32: Subtask load_rappers
[2022-10-05 19:00:02,702] {task_command.py:369} INFO - Running <TaskInstance: load_rappers_dag.load_rappers scheduled__2022-10-05T18:00:00+00:00 [running]> on host 39b88b75de04
[2022-10-05 19:00:02,819] {taskinstance.py:1571} INFO - Exporting the following env vars:
AIRFLOW_CTX_DAG_OWNER=***
AIRFLOW_CTX_DAG_ID=load_rappers_dag
AIRFLOW_CTX_TASK_ID=load_rappers
AIRFLOW_CTX_EXECUTION_DATE=2022-10-05T18:00:00+00:00
AIRFLOW_CTX_TRY_NUMBER=1
AIRFLOW_CTX_DAG_RUN_ID=scheduled__2022-10-05T18:00:00+00:00
[2022-10-05 19:00:02,820] {subprocess.py:62} INFO - Tmp dir root location: 
 /tmp
[2022-10-05 19:00:02,822] {subprocess.py:74} INFO - Running command: ['bash', '-c', 'python ${AIRFLOW_HOME}/scripts/load_rappers.py']
[2022-10-05 19:00:02,838] {subprocess.py:85} INFO - Output:
[2022-10-05 19:04:34,485] {subprocess.py:92} INFO - Compiling artist list...
[2022-10-05 19:04:34,493] {subprocess.py:92} INFO - Loading artists...
[2022-10-05 19:04:34,493] {subprocess.py:92} INFO - 502 artists loaded in 126.95 seconds
[2022-10-05 19:04:34,493] {subprocess.py:92} INFO - Loading tracks...
[2022-10-05 19:04:34,493] {subprocess.py:92} INFO - 2497 tracks loaded in 132.79 seconds
[2022-10-05 19:04:34,499] {subprocess.py:92} INFO - Traceback (most recent call last):
[2022-10-05 19:04:34,499] {subprocess.py:92} INFO -   File "/home/***/.local/lib/python3.7/site-packages/sqlalchemy/engine/base.py", line 3141, in _wrap_pool_connect
[2022-10-05 19:04:34,499] {subprocess.py:92} INFO -     return fn()
[2022-10-05 19:04:34,500] {subprocess.py:92} INFO -   File "/home/***/.local/lib/python3.7/site-packages/sqlalchemy/pool/base.py", line 301, in connect
[2022-10-05 19:04:34,500] {subprocess.py:92} INFO -     return _ConnectionFairy._checkout(self)
[2022-10-05 19:04:34,500] {subprocess.py:92} INFO -   File "/home/***/.local/lib/python3.7/site-packages/sqlalchemy/pool/base.py", line 755, in _checkout
[2022-10-05 19:04:34,500] {subprocess.py:92} INFO -     fairy = _ConnectionRecord.checkout(pool)
[2022-10-05 19:04:34,500] {subprocess.py:92} INFO -   File "/home/***/.local/lib/python3.7/site-packages/sqlalchemy/pool/base.py", line 419, in checkout
[2022-10-05 19:04:34,500] {subprocess.py:92} INFO -     rec = pool._do_get()
[2022-10-05 19:04:34,500] {subprocess.py:92} INFO -   File "/home/***/.local/lib/python3.7/site-packages/sqlalchemy/pool/impl.py", line 145, in _do_get
[2022-10-05 19:04:34,500] {subprocess.py:92} INFO -     self._dec_overflow()
[2022-10-05 19:04:34,500] {subprocess.py:92} INFO -   File "/home/***/.local/lib/python3.7/site-packages/sqlalchemy/util/langhelpers.py", line 72, in __exit__
[2022-10-05 19:04:34,500] {subprocess.py:92} INFO -     with_traceback=exc_tb,
[2022-10-05 19:04:34,500] {subprocess.py:92} INFO -   File "/home/***/.local/lib/python3.7/site-packages/sqlalchemy/util/compat.py", line 211, in raise_
[2022-10-05 19:04:34,500] {subprocess.py:92} INFO -     raise exception
[2022-10-05 19:04:34,500] {subprocess.py:92} INFO -   File "/home/***/.local/lib/python3.7/site-packages/sqlalchemy/pool/impl.py", line 142, in _do_get
[2022-10-05 19:04:34,500] {subprocess.py:92} INFO -     return self._create_connection()
[2022-10-05 19:04:34,500] {subprocess.py:92} INFO -   File "/home/***/.local/lib/python3.7/site-packages/sqlalchemy/pool/base.py", line 247, in _create_connection
[2022-10-05 19:04:34,500] {subprocess.py:92} INFO -     return _ConnectionRecord(self)
[2022-10-05 19:04:34,500] {subprocess.py:92} INFO -   File "/home/***/.local/lib/python3.7/site-packages/sqlalchemy/pool/base.py", line 362, in __init__
[2022-10-05 19:04:34,500] {subprocess.py:92} INFO -     self.__connect(first_connect_check=True)
[2022-10-05 19:04:34,500] {subprocess.py:92} INFO -   File "/home/***/.local/lib/python3.7/site-packages/sqlalchemy/pool/base.py", line 605, in __connect
[2022-10-05 19:04:34,500] {subprocess.py:92} INFO -     pool.logger.debug("Error on connect(): %s", e)
[2022-10-05 19:04:34,500] {subprocess.py:92} INFO -   File "/home/***/.local/lib/python3.7/site-packages/sqlalchemy/util/langhelpers.py", line 72, in __exit__
[2022-10-05 19:04:34,500] {subprocess.py:92} INFO -     with_traceback=exc_tb,
[2022-10-05 19:04:34,500] {subprocess.py:92} INFO -   File "/home/***/.local/lib/python3.7/site-packages/sqlalchemy/util/compat.py", line 211, in raise_
[2022-10-05 19:04:34,500] {subprocess.py:92} INFO -     raise exception
[2022-10-05 19:04:34,500] {subprocess.py:92} INFO -   File "/home/***/.local/lib/python3.7/site-packages/sqlalchemy/pool/base.py", line 599, in __connect
[2022-10-05 19:04:34,500] {subprocess.py:92} INFO -     connection = pool._invoke_creator(self)
[2022-10-05 19:04:34,500] {subprocess.py:92} INFO -   File "/home/***/.local/lib/python3.7/site-packages/sqlalchemy/engine/create.py", line 578, in connect
[2022-10-05 19:04:34,500] {subprocess.py:92} INFO -     return dialect.connect(*cargs, **cparams)
[2022-10-05 19:04:34,500] {subprocess.py:92} INFO -   File "/home/***/.local/lib/python3.7/site-packages/sqlalchemy/engine/default.py", line 583, in connect
[2022-10-05 19:04:34,501] {subprocess.py:92} INFO -     return self.dbapi.connect(*cargs, **cparams)
[2022-10-05 19:04:34,501] {subprocess.py:92} INFO -   File "/home/***/.local/lib/python3.7/site-packages/psycopg2/__init__.py", line 122, in connect
[2022-10-05 19:04:34,501] {subprocess.py:92} INFO -     conn = _connect(dsn, connection_factory=connection_factory, **kwasync)
[2022-10-05 19:04:34,501] {subprocess.py:92} INFO - psycopg2.OperationalError: connection to server at "127.0.0.1", port 5432 failed: Connection refused
[2022-10-05 19:04:34,501] {subprocess.py:92} INFO - 	Is the server running on that host and accepting TCP/IP connections?
[2022-10-05 19:04:34,501] {subprocess.py:92} INFO - 
[2022-10-05 19:04:34,501] {subprocess.py:92} INFO - 
[2022-10-05 19:04:34,501] {subprocess.py:92} INFO - The above exception was the direct cause of the following exception:
[2022-10-05 19:04:34,501] {subprocess.py:92} INFO - 
[2022-10-05 19:04:34,501] {subprocess.py:92} INFO - Traceback (most recent call last):
[2022-10-05 19:04:34,501] {subprocess.py:92} INFO -   File "/opt/***/scripts/load_rappers.py", line 64, in <module>
[2022-10-05 19:04:34,501] {subprocess.py:92} INFO -     Base.metadata.create_all(engine)
[2022-10-05 19:04:34,502] {subprocess.py:92} INFO -   File "/home/***/.local/lib/python3.7/site-packages/sqlalchemy/sql/schema.py", line 4745, in create_all
[2022-10-05 19:04:34,502] {subprocess.py:92} INFO -     ddl.SchemaGenerator, self, checkfirst=checkfirst, tables=tables
[2022-10-05 19:04:34,502] {subprocess.py:92} INFO -   File "/home/***/.local/lib/python3.7/site-packages/sqlalchemy/engine/base.py", line 3007, in _run_ddl_visitor
[2022-10-05 19:04:34,502] {subprocess.py:92} INFO -     with self.begin() as conn:
[2022-10-05 19:04:34,502] {subprocess.py:92} INFO -   File "/home/***/.local/lib/python3.7/site-packages/sqlalchemy/engine/base.py", line 2923, in begin
[2022-10-05 19:04:34,503] {subprocess.py:92} INFO -     conn = self.connect(close_with_result=close_with_result)
[2022-10-05 19:04:34,503] {subprocess.py:92} INFO -   File "/home/***/.local/lib/python3.7/site-packages/sqlalchemy/engine/base.py", line 3095, in connect
[2022-10-05 19:04:34,503] {subprocess.py:92} INFO -     return self._connection_cls(self, close_with_result=close_with_result)
[2022-10-05 19:04:34,503] {subprocess.py:92} INFO -   File "/home/***/.local/lib/python3.7/site-packages/sqlalchemy/engine/base.py", line 91, in __init__
[2022-10-05 19:04:34,503] {subprocess.py:92} INFO -     else engine.raw_connection()
[2022-10-05 19:04:34,503] {subprocess.py:92} INFO -   File "/home/***/.local/lib/python3.7/site-packages/sqlalchemy/engine/base.py", line 3174, in raw_connection
[2022-10-05 19:04:34,503] {subprocess.py:92} INFO -     return self._wrap_pool_connect(self.pool.connect, _connection)
[2022-10-05 19:04:34,503] {subprocess.py:92} INFO -   File "/home/***/.local/lib/python3.7/site-packages/sqlalchemy/engine/base.py", line 3145, in _wrap_pool_connect
[2022-10-05 19:04:34,503] {subprocess.py:92} INFO -     e, dialect, self
[2022-10-05 19:04:34,503] {subprocess.py:92} INFO -   File "/home/***/.local/lib/python3.7/site-packages/sqlalchemy/engine/base.py", line 2004, in _handle_dbapi_exception_noconnection
[2022-10-05 19:04:34,503] {subprocess.py:92} INFO -     sqlalchemy_exception, with_traceback=exc_info[2], from_=e
[2022-10-05 19:04:34,503] {subprocess.py:92} INFO -   File "/home/***/.local/lib/python3.7/site-packages/sqlalchemy/util/compat.py", line 211, in raise_
[2022-10-05 19:04:34,503] {subprocess.py:92} INFO -     raise exception
[2022-10-05 19:04:34,503] {subprocess.py:92} INFO -   File "/home/***/.local/lib/python3.7/site-packages/sqlalchemy/engine/base.py", line 3141, in _wrap_pool_connect
[2022-10-05 19:04:34,503] {subprocess.py:92} INFO -     return fn()
[2022-10-05 19:04:34,503] {subprocess.py:92} INFO -   File "/home/***/.local/lib/python3.7/site-packages/sqlalchemy/pool/base.py", line 301, in connect
[2022-10-05 19:04:34,503] {subprocess.py:92} INFO -     return _ConnectionFairy._checkout(self)
[2022-10-05 19:04:34,503] {subprocess.py:92} INFO -   File "/home/***/.local/lib/python3.7/site-packages/sqlalchemy/pool/base.py", line 755, in _checkout
[2022-10-05 19:04:34,503] {subprocess.py:92} INFO -     fairy = _ConnectionRecord.checkout(pool)
[2022-10-05 19:04:34,503] {subprocess.py:92} INFO -   File "/home/***/.local/lib/python3.7/site-packages/sqlalchemy/pool/base.py", line 419, in checkout
[2022-10-05 19:04:34,503] {subprocess.py:92} INFO -     rec = pool._do_get()
[2022-10-05 19:04:34,503] {subprocess.py:92} INFO -   File "/home/***/.local/lib/python3.7/site-packages/sqlalchemy/pool/impl.py", line 145, in _do_get
[2022-10-05 19:04:34,504] {subprocess.py:92} INFO -     self._dec_overflow()
[2022-10-05 19:04:34,504] {subprocess.py:92} INFO -   File "/home/***/.local/lib/python3.7/site-packages/sqlalchemy/util/langhelpers.py", line 72, in __exit__
[2022-10-05 19:04:34,504] {subprocess.py:92} INFO -     with_traceback=exc_tb,
[2022-10-05 19:04:34,504] {subprocess.py:92} INFO -   File "/home/***/.local/lib/python3.7/site-packages/sqlalchemy/util/compat.py", line 211, in raise_
[2022-10-05 19:04:34,504] {subprocess.py:92} INFO -     raise exception
[2022-10-05 19:04:34,504] {subprocess.py:92} INFO -   File "/home/***/.local/lib/python3.7/site-packages/sqlalchemy/pool/impl.py", line 142, in _do_get
[2022-10-05 19:04:34,504] {subprocess.py:92} INFO -     return self._create_connection()
[2022-10-05 19:04:34,504] {subprocess.py:92} INFO -   File "/home/***/.local/lib/python3.7/site-packages/sqlalchemy/pool/base.py", line 247, in _create_connection
[2022-10-05 19:04:34,504] {subprocess.py:92} INFO -     return _ConnectionRecord(self)
[2022-10-05 19:04:34,504] {subprocess.py:92} INFO -   File "/home/***/.local/lib/python3.7/site-packages/sqlalchemy/pool/base.py", line 362, in __init__
[2022-10-05 19:04:34,504] {subprocess.py:92} INFO -     self.__connect(first_connect_check=True)
[2022-10-05 19:04:34,504] {subprocess.py:92} INFO -   File "/home/***/.local/lib/python3.7/site-packages/sqlalchemy/pool/base.py", line 605, in __connect
[2022-10-05 19:04:34,504] {subprocess.py:92} INFO -     pool.logger.debug("Error on connect(): %s", e)
[2022-10-05 19:04:34,504] {subprocess.py:92} INFO -   File "/home/***/.local/lib/python3.7/site-packages/sqlalchemy/util/langhelpers.py", line 72, in __exit__
[2022-10-05 19:04:34,504] {subprocess.py:92} INFO -     with_traceback=exc_tb,
[2022-10-05 19:04:34,504] {subprocess.py:92} INFO -   File "/home/***/.local/lib/python3.7/site-packages/sqlalchemy/util/compat.py", line 211, in raise_
[2022-10-05 19:04:34,504] {subprocess.py:92} INFO -     raise exception
[2022-10-05 19:04:34,519] {subprocess.py:92} INFO -   File "/home/***/.local/lib/python3.7/site-packages/sqlalchemy/pool/base.py", line 599, in __connect
[2022-10-05 19:04:34,519] {subprocess.py:92} INFO -     connection = pool._invoke_creator(self)
[2022-10-05 19:04:34,519] {subprocess.py:92} INFO -   File "/home/***/.local/lib/python3.7/site-packages/sqlalchemy/engine/create.py", line 578, in connect
[2022-10-05 19:04:34,519] {subprocess.py:92} INFO -     return dialect.connect(*cargs, **cparams)
[2022-10-05 19:04:34,519] {subprocess.py:92} INFO -   File "/home/***/.local/lib/python3.7/site-packages/sqlalchemy/engine/default.py", line 583, in connect
[2022-10-05 19:04:34,519] {subprocess.py:92} INFO -     return self.dbapi.connect(*cargs, **cparams)
[2022-10-05 19:04:34,519] {subprocess.py:92} INFO -   File "/home/***/.local/lib/python3.7/site-packages/psycopg2/__init__.py", line 122, in connect
[2022-10-05 19:04:34,519] {subprocess.py:92} INFO -     conn = _connect(dsn, connection_factory=connection_factory, **kwasync)
[2022-10-05 19:04:34,519] {subprocess.py:92} INFO - sqlalchemy.exc.OperationalError: (psycopg2.OperationalError) connection to server at "127.0.0.1", port 5432 failed: Connection refused
[2022-10-05 19:04:34,519] {subprocess.py:92} INFO - 	Is the server running on that host and accepting TCP/IP connections?
[2022-10-05 19:04:34,519] {subprocess.py:92} INFO - 
[2022-10-05 19:04:34,519] {subprocess.py:92} INFO - (Background on this error at: http://sqlalche.me/e/14/e3q8)
[2022-10-05 19:04:34,671] {subprocess.py:96} INFO - Command exited with return code 1
[2022-10-05 19:04:34,753] {taskinstance.py:1889} ERROR - Task failed with exception
Traceback (most recent call last):
  File "/home/airflow/.local/lib/python3.7/site-packages/airflow/operators/bash.py", line 195, in execute
    f'Bash command failed. The command returned a non-zero exit code {result.exit_code}.'
airflow.exceptions.AirflowException: Bash command failed. The command returned a non-zero exit code 1.
[2022-10-05 19:04:34,768] {taskinstance.py:1400} INFO - Marking task as FAILED. dag_id=load_rappers_dag, task_id=load_rappers, execution_date=20221005T180000, start_date=20221005T190002, end_date=20221005T190434
[2022-10-05 19:04:34,806] {standard_task_runner.py:97} ERROR - Failed to execute job 32 for task load_rappers (Bash command failed. The command returned a non-zero exit code 1.; 1032)
[2022-10-05 19:04:34,853] {local_task_job.py:156} INFO - Task exited with return code 1
[2022-10-05 19:04:34,913] {local_task_job.py:273} INFO - 0 downstream tasks scheduled from follow-on schedule check
[2022-10-07 17:19:01,872] {taskinstance.py:1159} INFO - Dependencies all met for <TaskInstance: load_rappers_dag.load_rappers scheduled__2022-10-05T18:00:00+00:00 [queued]>
[2022-10-07 17:19:01,899] {taskinstance.py:1159} INFO - Dependencies all met for <TaskInstance: load_rappers_dag.load_rappers scheduled__2022-10-05T18:00:00+00:00 [queued]>
[2022-10-07 17:19:01,899] {taskinstance.py:1356} INFO - 
--------------------------------------------------------------------------------
[2022-10-07 17:19:01,899] {taskinstance.py:1357} INFO - Starting attempt 1 of 1
[2022-10-07 17:19:01,900] {taskinstance.py:1358} INFO - 
--------------------------------------------------------------------------------
[2022-10-07 17:19:01,945] {taskinstance.py:1377} INFO - Executing <Task(BashOperator): load_rappers> on 2022-10-05 18:00:00+00:00
[2022-10-07 17:19:01,953] {standard_task_runner.py:52} INFO - Started process 1742 to run task
[2022-10-07 17:19:01,963] {standard_task_runner.py:79} INFO - Running: ['***', 'tasks', 'run', 'load_rappers_dag', 'load_rappers', 'scheduled__2022-10-05T18:00:00+00:00', '--job-id', '20', '--raw', '--subdir', 'DAGS_FOLDER/load_rappers_dag.py', '--cfg-path', '/tmp/tmptzw51ucc', '--error-file', '/tmp/tmp044hu64j']
[2022-10-07 17:19:01,965] {standard_task_runner.py:80} INFO - Job 20: Subtask load_rappers
[2022-10-07 17:19:02,172] {task_command.py:369} INFO - Running <TaskInstance: load_rappers_dag.load_rappers scheduled__2022-10-05T18:00:00+00:00 [running]> on host 84650b6b2dfc
[2022-10-07 17:19:02,453] {taskinstance.py:1571} INFO - Exporting the following env vars:
AIRFLOW_CTX_DAG_OWNER=***
AIRFLOW_CTX_DAG_ID=load_rappers_dag
AIRFLOW_CTX_TASK_ID=load_rappers
AIRFLOW_CTX_EXECUTION_DATE=2022-10-05T18:00:00+00:00
AIRFLOW_CTX_TRY_NUMBER=1
AIRFLOW_CTX_DAG_RUN_ID=scheduled__2022-10-05T18:00:00+00:00
[2022-10-07 17:19:02,468] {subprocess.py:62} INFO - Tmp dir root location: 
 /tmp
[2022-10-07 17:19:02,469] {subprocess.py:74} INFO - Running command: ['bash', '-c', 'python ${AIRFLOW_HOME}/scripts/load_rappers.py']
[2022-10-07 17:19:02,503] {subprocess.py:85} INFO - Output:
[2022-10-07 17:19:09,502] {subprocess.py:92} INFO - Compiling artist list...
[2022-10-07 17:19:09,503] {subprocess.py:92} INFO - Traceback (most recent call last):
[2022-10-07 17:19:09,503] {subprocess.py:92} INFO -   File "/opt/***/scripts/load_rappers.py", line 82, in <module>
[2022-10-07 17:19:09,504] {subprocess.py:92} INFO -     main()
[2022-10-07 17:19:09,504] {subprocess.py:92} INFO -   File "/opt/***/scripts/load_rappers.py", line 73, in main
[2022-10-07 17:19:09,504] {subprocess.py:92} INFO -     combinedArtists = compile_artists(lister, genreDict, playlistDict)
[2022-10-07 17:19:09,504] {subprocess.py:92} INFO -   File "/opt/***/scripts/load_rappers.py", line 38, in compile_artists
[2022-10-07 17:19:09,504] {subprocess.py:92} INFO -     return lister.combine_artists(genreDict, playlistDict)
[2022-10-07 17:19:09,504] {subprocess.py:92} INFO -   File "/opt/***/scripts/artist_lister.py", line 38, in combine_artists
[2022-10-07 17:19:09,504] {subprocess.py:92} INFO -     artistDict = self.union_dict(artistDict, self.parse_search(k, v))
[2022-10-07 17:19:09,504] {subprocess.py:92} INFO -   File "/opt/***/scripts/artist_lister.py", line 16, in parse_search
[2022-10-07 17:19:09,504] {subprocess.py:92} INFO -     for i in range(len(payload['artists']['items'])):
[2022-10-07 17:19:09,504] {subprocess.py:92} INFO - KeyError: 'artists'
[2022-10-07 17:19:09,775] {subprocess.py:96} INFO - Command exited with return code 1
[2022-10-07 17:19:09,823] {taskinstance.py:1889} ERROR - Task failed with exception
Traceback (most recent call last):
  File "/home/airflow/.local/lib/python3.7/site-packages/airflow/operators/bash.py", line 195, in execute
    f'Bash command failed. The command returned a non-zero exit code {result.exit_code}.'
airflow.exceptions.AirflowException: Bash command failed. The command returned a non-zero exit code 1.
[2022-10-07 17:19:09,832] {taskinstance.py:1400} INFO - Marking task as FAILED. dag_id=load_rappers_dag, task_id=load_rappers, execution_date=20221005T180000, start_date=20221007T171901, end_date=20221007T171909
[2022-10-07 17:19:09,856] {standard_task_runner.py:97} ERROR - Failed to execute job 20 for task load_rappers (Bash command failed. The command returned a non-zero exit code 1.; 1742)
[2022-10-07 17:19:09,904] {local_task_job.py:156} INFO - Task exited with return code 1
[2022-10-07 17:19:09,990] {local_task_job.py:273} INFO - 0 downstream tasks scheduled from follow-on schedule check
