[2022-10-07 17:17:18,746] {taskinstance.py:1159} INFO - Dependencies all met for <TaskInstance: load_rappers_dag.load_rappers scheduled__2022-10-05T06:00:00+00:00 [queued]>
[2022-10-07 17:17:18,799] {taskinstance.py:1159} INFO - Dependencies all met for <TaskInstance: load_rappers_dag.load_rappers scheduled__2022-10-05T06:00:00+00:00 [queued]>
[2022-10-07 17:17:18,800] {taskinstance.py:1356} INFO - 
--------------------------------------------------------------------------------
[2022-10-07 17:17:18,800] {taskinstance.py:1357} INFO - Starting attempt 1 of 1
[2022-10-07 17:17:18,800] {taskinstance.py:1358} INFO - 
--------------------------------------------------------------------------------
[2022-10-07 17:17:18,920] {taskinstance.py:1377} INFO - Executing <Task(BashOperator): load_rappers> on 2022-10-05 06:00:00+00:00
[2022-10-07 17:17:18,931] {standard_task_runner.py:52} INFO - Started process 1514 to run task
[2022-10-07 17:17:19,049] {standard_task_runner.py:79} INFO - Running: ['***', 'tasks', 'run', 'load_rappers_dag', 'load_rappers', 'scheduled__2022-10-05T06:00:00+00:00', '--job-id', '11', '--raw', '--subdir', 'DAGS_FOLDER/load_rappers_dag.py', '--cfg-path', '/tmp/tmp31p_6549', '--error-file', '/tmp/tmp81yskjvj']
[2022-10-07 17:17:19,083] {standard_task_runner.py:80} INFO - Job 11: Subtask load_rappers
[2022-10-07 17:17:20,998] {task_command.py:369} INFO - Running <TaskInstance: load_rappers_dag.load_rappers scheduled__2022-10-05T06:00:00+00:00 [running]> on host 84650b6b2dfc
[2022-10-07 17:17:22,653] {taskinstance.py:1571} INFO - Exporting the following env vars:
AIRFLOW_CTX_DAG_OWNER=***
AIRFLOW_CTX_DAG_ID=load_rappers_dag
AIRFLOW_CTX_TASK_ID=load_rappers
AIRFLOW_CTX_EXECUTION_DATE=2022-10-05T06:00:00+00:00
AIRFLOW_CTX_TRY_NUMBER=1
AIRFLOW_CTX_DAG_RUN_ID=scheduled__2022-10-05T06:00:00+00:00
[2022-10-07 17:17:22,670] {subprocess.py:62} INFO - Tmp dir root location: 
 /tmp
[2022-10-07 17:17:22,683] {subprocess.py:74} INFO - Running command: ['bash', '-c', 'python ${AIRFLOW_HOME}/scripts/load_rappers.py']
[2022-10-07 17:17:22,748] {subprocess.py:85} INFO - Output:
[2022-10-07 17:18:44,781] {subprocess.py:92} INFO - Compiling artist list...
[2022-10-07 17:18:44,874] {subprocess.py:92} INFO - Loading artists...
[2022-10-07 17:18:45,157] {subprocess.py:92} INFO - Traceback (most recent call last):
[2022-10-07 17:18:45,159] {subprocess.py:92} INFO -   File "/home/***/.local/lib/python3.7/site-packages/urllib3/connectionpool.py", line 710, in urlopen
[2022-10-07 17:18:45,159] {subprocess.py:92} INFO -     chunked=chunked,
[2022-10-07 17:18:45,160] {subprocess.py:92} INFO -   File "/home/***/.local/lib/python3.7/site-packages/urllib3/connectionpool.py", line 449, in _make_request
[2022-10-07 17:18:45,160] {subprocess.py:92} INFO -     six.raise_from(e, None)
[2022-10-07 17:18:45,160] {subprocess.py:92} INFO -   File "<string>", line 3, in raise_from
[2022-10-07 17:18:45,160] {subprocess.py:92} INFO -   File "/home/***/.local/lib/python3.7/site-packages/urllib3/connectionpool.py", line 444, in _make_request
[2022-10-07 17:18:45,160] {subprocess.py:92} INFO -     httplib_response = conn.getresponse()
[2022-10-07 17:18:45,160] {subprocess.py:92} INFO -   File "/usr/local/lib/python3.7/http/client.py", line 1373, in getresponse
[2022-10-07 17:18:45,161] {subprocess.py:92} INFO -     response.begin()
[2022-10-07 17:18:45,161] {subprocess.py:92} INFO -   File "/usr/local/lib/python3.7/http/client.py", line 319, in begin
[2022-10-07 17:18:45,161] {subprocess.py:92} INFO -     version, status, reason = self._read_status()
[2022-10-07 17:18:45,161] {subprocess.py:92} INFO -   File "/usr/local/lib/python3.7/http/client.py", line 288, in _read_status
[2022-10-07 17:18:45,161] {subprocess.py:92} INFO -     raise RemoteDisconnected("Remote end closed connection without"
[2022-10-07 17:18:45,161] {subprocess.py:92} INFO - http.client.RemoteDisconnected: Remote end closed connection without response
[2022-10-07 17:18:45,161] {subprocess.py:92} INFO - 
[2022-10-07 17:18:45,161] {subprocess.py:92} INFO - During handling of the above exception, another exception occurred:
[2022-10-07 17:18:45,161] {subprocess.py:92} INFO - 
[2022-10-07 17:18:45,161] {subprocess.py:92} INFO - Traceback (most recent call last):
[2022-10-07 17:18:45,161] {subprocess.py:92} INFO -   File "/home/***/.local/lib/python3.7/site-packages/requests/adapters.py", line 450, in send
[2022-10-07 17:18:45,161] {subprocess.py:92} INFO -     timeout=timeout
[2022-10-07 17:18:45,161] {subprocess.py:92} INFO -   File "/home/***/.local/lib/python3.7/site-packages/urllib3/connectionpool.py", line 786, in urlopen
[2022-10-07 17:18:45,161] {subprocess.py:92} INFO -     method, url, error=e, _pool=self, _stacktrace=sys.exc_info()[2]
[2022-10-07 17:18:45,161] {subprocess.py:92} INFO -   File "/home/***/.local/lib/python3.7/site-packages/urllib3/util/retry.py", line 550, in increment
[2022-10-07 17:18:45,161] {subprocess.py:92} INFO -     raise six.reraise(type(error), error, _stacktrace)
[2022-10-07 17:18:45,161] {subprocess.py:92} INFO -   File "/home/***/.local/lib/python3.7/site-packages/urllib3/packages/six.py", line 769, in reraise
[2022-10-07 17:18:45,161] {subprocess.py:92} INFO -     raise value.with_traceback(tb)
[2022-10-07 17:18:45,162] {subprocess.py:92} INFO -   File "/home/***/.local/lib/python3.7/site-packages/urllib3/connectionpool.py", line 710, in urlopen
[2022-10-07 17:18:45,162] {subprocess.py:92} INFO -     chunked=chunked,
[2022-10-07 17:18:45,162] {subprocess.py:92} INFO -   File "/home/***/.local/lib/python3.7/site-packages/urllib3/connectionpool.py", line 449, in _make_request
[2022-10-07 17:18:45,162] {subprocess.py:92} INFO -     six.raise_from(e, None)
[2022-10-07 17:18:45,162] {subprocess.py:92} INFO -   File "<string>", line 3, in raise_from
[2022-10-07 17:18:45,162] {subprocess.py:92} INFO -   File "/home/***/.local/lib/python3.7/site-packages/urllib3/connectionpool.py", line 444, in _make_request
[2022-10-07 17:18:45,162] {subprocess.py:92} INFO -     httplib_response = conn.getresponse()
[2022-10-07 17:18:45,162] {subprocess.py:92} INFO -   File "/usr/local/lib/python3.7/http/client.py", line 1373, in getresponse
[2022-10-07 17:18:45,162] {subprocess.py:92} INFO -     response.begin()
[2022-10-07 17:18:45,162] {subprocess.py:92} INFO -   File "/usr/local/lib/python3.7/http/client.py", line 319, in begin
[2022-10-07 17:18:45,162] {subprocess.py:92} INFO -     version, status, reason = self._read_status()
[2022-10-07 17:18:45,162] {subprocess.py:92} INFO -   File "/usr/local/lib/python3.7/http/client.py", line 288, in _read_status
[2022-10-07 17:18:45,162] {subprocess.py:92} INFO -     raise RemoteDisconnected("Remote end closed connection without"
[2022-10-07 17:18:45,162] {subprocess.py:92} INFO - urllib3.exceptions.ProtocolError: ('Connection aborted.', RemoteDisconnected('Remote end closed connection without response'))
[2022-10-07 17:18:45,179] {subprocess.py:92} INFO - 
[2022-10-07 17:18:45,179] {subprocess.py:92} INFO - During handling of the above exception, another exception occurred:
[2022-10-07 17:18:45,179] {subprocess.py:92} INFO - 
[2022-10-07 17:18:45,179] {subprocess.py:92} INFO - Traceback (most recent call last):
[2022-10-07 17:18:45,179] {subprocess.py:92} INFO -   File "/opt/***/scripts/load_rappers.py", line 82, in <module>
[2022-10-07 17:18:45,180] {subprocess.py:92} INFO -     main()
[2022-10-07 17:18:45,180] {subprocess.py:92} INFO -   File "/opt/***/scripts/load_rappers.py", line 74, in main
[2022-10-07 17:18:45,180] {subprocess.py:92} INFO -     dfRappers = get_artist_data(lister, combinedArtists)
[2022-10-07 17:18:45,180] {subprocess.py:92} INFO -   File "/opt/***/scripts/load_rappers.py", line 43, in get_artist_data
[2022-10-07 17:18:45,181] {subprocess.py:92} INFO -     dfRappers = pd.DataFrame(lister.pull_artist_data(combinedArtists))
[2022-10-07 17:18:45,181] {subprocess.py:92} INFO -   File "/opt/***/scripts/artist_lister.py", line 49, in pull_artist_data
[2022-10-07 17:18:45,181] {subprocess.py:92} INFO -     payload = self.get_artist(i)
[2022-10-07 17:18:45,181] {subprocess.py:92} INFO -   File "/opt/***/scripts/spotify_client.py", line 96, in get_artist
[2022-10-07 17:18:45,181] {subprocess.py:92} INFO -     return self.get_resource(_id, resource_type='artists')
[2022-10-07 17:18:45,181] {subprocess.py:92} INFO -   File "/opt/***/scripts/spotify_client.py", line 81, in get_resource
[2022-10-07 17:18:45,182] {subprocess.py:92} INFO -     r = requests.get(endpoint, headers=headers)
[2022-10-07 17:18:45,183] {subprocess.py:92} INFO -   File "/home/***/.local/lib/python3.7/site-packages/requests/api.py", line 75, in get
[2022-10-07 17:18:45,183] {subprocess.py:92} INFO -     return request('get', url, params=params, **kwargs)
[2022-10-07 17:18:45,215] {subprocess.py:92} INFO -   File "/home/***/.local/lib/python3.7/site-packages/requests/api.py", line 61, in request
[2022-10-07 17:18:45,215] {subprocess.py:92} INFO -     return session.request(method=method, url=url, **kwargs)
[2022-10-07 17:18:45,215] {subprocess.py:92} INFO -   File "/home/***/.local/lib/python3.7/site-packages/requests/sessions.py", line 529, in request
[2022-10-07 17:18:45,215] {subprocess.py:92} INFO -     resp = self.send(prep, **send_kwargs)
[2022-10-07 17:18:45,215] {subprocess.py:92} INFO -   File "/home/***/.local/lib/python3.7/site-packages/requests/sessions.py", line 645, in send
[2022-10-07 17:18:45,215] {subprocess.py:92} INFO -     r = adapter.send(request, **kwargs)
[2022-10-07 17:18:45,215] {subprocess.py:92} INFO -   File "/home/***/.local/lib/python3.7/site-packages/requests/adapters.py", line 501, in send
[2022-10-07 17:18:45,215] {subprocess.py:92} INFO -     raise ConnectionError(err, request=request)
[2022-10-07 17:18:45,215] {subprocess.py:92} INFO - requests.exceptions.ConnectionError: ('Connection aborted.', RemoteDisconnected('Remote end closed connection without response'))
[2022-10-07 17:18:46,380] {subprocess.py:96} INFO - Command exited with return code 1
[2022-10-07 17:18:46,970] {taskinstance.py:1889} ERROR - Task failed with exception
Traceback (most recent call last):
  File "/home/airflow/.local/lib/python3.7/site-packages/airflow/operators/bash.py", line 195, in execute
    f'Bash command failed. The command returned a non-zero exit code {result.exit_code}.'
airflow.exceptions.AirflowException: Bash command failed. The command returned a non-zero exit code 1.
[2022-10-07 17:18:47,157] {taskinstance.py:1400} INFO - Marking task as FAILED. dag_id=load_rappers_dag, task_id=load_rappers, execution_date=20221005T060000, start_date=20221007T171718, end_date=20221007T171847
[2022-10-07 17:18:47,764] {standard_task_runner.py:97} ERROR - Failed to execute job 11 for task load_rappers (Bash command failed. The command returned a non-zero exit code 1.; 1514)
[2022-10-07 17:18:47,886] {local_task_job.py:156} INFO - Task exited with return code 1
[2022-10-07 17:18:48,923] {local_task_job.py:273} INFO - 0 downstream tasks scheduled from follow-on schedule check
