[2022-10-15 21:19:24,615] {taskinstance.py:1159} INFO - Dependencies all met for <TaskInstance: load_rappers_dag_pyop.load_rappers_to_gcs manual__2022-10-15T21:19:09.484467+00:00 [queued]>
[2022-10-15 21:19:24,627] {taskinstance.py:1159} INFO - Dependencies all met for <TaskInstance: load_rappers_dag_pyop.load_rappers_to_gcs manual__2022-10-15T21:19:09.484467+00:00 [queued]>
[2022-10-15 21:19:24,627] {taskinstance.py:1356} INFO - 
--------------------------------------------------------------------------------
[2022-10-15 21:19:24,627] {taskinstance.py:1357} INFO - Starting attempt 1 of 1
[2022-10-15 21:19:24,627] {taskinstance.py:1358} INFO - 
--------------------------------------------------------------------------------
[2022-10-15 21:19:24,642] {taskinstance.py:1377} INFO - Executing <Task(PostgresToGCSOperator): load_rappers_to_gcs> on 2022-10-15 21:19:09.484467+00:00
[2022-10-15 21:19:24,655] {standard_task_runner.py:52} INFO - Started process 5933 to run task
[2022-10-15 21:19:24,723] {standard_task_runner.py:79} INFO - Running: ['***', 'tasks', 'run', 'load_rappers_dag_pyop', 'load_rappers_to_gcs', 'manual__2022-10-15T21:19:09.484467+00:00', '--job-id', '26', '--raw', '--subdir', 'DAGS_FOLDER/load_rappers_dag_pyop.py', '--cfg-path', '/tmp/tmpo2kxovss', '--error-file', '/tmp/tmp8yjhj31c']
[2022-10-15 21:19:24,724] {standard_task_runner.py:80} INFO - Job 26: Subtask load_rappers_to_gcs
[2022-10-15 21:19:25,177] {task_command.py:369} INFO - Running <TaskInstance: load_rappers_dag_pyop.load_rappers_to_gcs manual__2022-10-15T21:19:09.484467+00:00 [running]> on host 6300e87c6973
[2022-10-15 21:19:25,486] {taskinstance.py:1571} INFO - Exporting the following env vars:
AIRFLOW_CTX_DAG_OWNER=***
AIRFLOW_CTX_DAG_ID=load_rappers_dag_pyop
AIRFLOW_CTX_TASK_ID=load_rappers_to_gcs
AIRFLOW_CTX_EXECUTION_DATE=2022-10-15T21:19:09.484467+00:00
AIRFLOW_CTX_TRY_NUMBER=1
AIRFLOW_CTX_DAG_RUN_ID=manual__2022-10-15T21:19:09.484467+00:00
[2022-10-15 21:19:25,489] {sql_to_gcs.py:139} INFO - Executing query
[2022-10-15 21:19:25,518] {base.py:68} INFO - Using connection ID 'postgres-dc' for task execution.
[2022-10-15 21:19:25,536] {sql_to_gcs.py:155} INFO - Writing local data files
[2022-10-15 21:19:25,538] {sql_to_gcs.py:160} INFO - Uploading chunk file #0 to GCS.
[2022-10-15 21:19:25,544] {base.py:68} INFO - Using connection ID 'gcp_test' for task execution.
[2022-10-15 21:19:26,217] {gcs.py:486} ERROR - Upload attempt of object: rappers/rappers.csv from rappers/rappers.csv has failed. Attempt: 1, max 1.
[2022-10-15 21:19:26,218] {taskinstance.py:1889} ERROR - Task failed with exception
Traceback (most recent call last):
  File "/home/airflow/.local/lib/python3.7/site-packages/google/cloud/storage/blob.py", line 2594, in upload_from_file
    retry=retry,
  File "/home/airflow/.local/lib/python3.7/site-packages/google/cloud/storage/blob.py", line 2396, in _do_upload
    retry=retry,
  File "/home/airflow/.local/lib/python3.7/site-packages/google/cloud/storage/blob.py", line 1917, in _do_multipart_upload
    transport, data, object_metadata, content_type, timeout=timeout
  File "/home/airflow/.local/lib/python3.7/site-packages/google/resumable_media/requests/upload.py", line 154, in transmit
    retriable_request, self._get_status_code, self._retry_strategy
  File "/home/airflow/.local/lib/python3.7/site-packages/google/resumable_media/requests/_request_helpers.py", line 147, in wait_and_retry
    response = func()
  File "/home/airflow/.local/lib/python3.7/site-packages/google/resumable_media/requests/upload.py", line 149, in retriable_request
    self._process_response(result)
  File "/home/airflow/.local/lib/python3.7/site-packages/google/resumable_media/_upload.py", line 114, in _process_response
    _helpers.require_status_code(response, (http.client.OK,), self._get_status_code)
  File "/home/airflow/.local/lib/python3.7/site-packages/google/resumable_media/_helpers.py", line 110, in require_status_code
    *status_codes
google.resumable_media.common.InvalidResponse: ('Request failed with status code', 403, 'Expected one of', <HTTPStatus.OK: 200>)

During handling of the above exception, another exception occurred:

Traceback (most recent call last):
  File "/home/airflow/.local/lib/python3.7/site-packages/airflow/providers/google/cloud/transfers/sql_to_gcs.py", line 161, in execute
    self._upload_to_gcs(file_to_upload)
  File "/home/airflow/.local/lib/python3.7/site-packages/airflow/providers/google/cloud/transfers/sql_to_gcs.py", line 358, in _upload_to_gcs
    gzip=self.gzip if file_to_upload.get('file_name') != self.schema_filename else False,
  File "/home/airflow/.local/lib/python3.7/site-packages/airflow/providers/google/cloud/hooks/gcs.py", line 520, in upload
    partial(blob.upload_from_filename, filename=filename, content_type=mime_type, timeout=timeout)
  File "/home/airflow/.local/lib/python3.7/site-packages/airflow/providers/google/cloud/hooks/gcs.py", line 488, in _call_with_retry
    raise e
  File "/home/airflow/.local/lib/python3.7/site-packages/airflow/providers/google/cloud/hooks/gcs.py", line 477, in _call_with_retry
    f()
  File "/home/airflow/.local/lib/python3.7/site-packages/google/cloud/storage/blob.py", line 2735, in upload_from_filename
    retry=retry,
  File "/home/airflow/.local/lib/python3.7/site-packages/google/cloud/storage/blob.py", line 2598, in upload_from_file
    _raise_from_invalid_response(exc)
  File "/home/airflow/.local/lib/python3.7/site-packages/google/cloud/storage/blob.py", line 4470, in _raise_from_invalid_response
    raise exceptions.from_http_status(response.status_code, message, response=response)
google.api_core.exceptions.Forbidden: 403 POST https://storage.googleapis.com/upload/storage/v1/b/raw_battle_rap/o?uploadType=multipart: {
  "error": {
    "code": 403,
    "message": "sqlalchemy@battle-rap-365403.iam.gserviceaccount.com does not have storage.objects.create access to the Google Cloud Storage object.",
    "errors": [
      {
        "message": "sqlalchemy@battle-rap-365403.iam.gserviceaccount.com does not have storage.objects.create access to the Google Cloud Storage object.",
        "domain": "global",
        "reason": "forbidden"
      }
    ]
  }
}
: ('Request failed with status code', 403, 'Expected one of', <HTTPStatus.OK: 200>)
[2022-10-15 21:19:26,281] {taskinstance.py:1400} INFO - Marking task as FAILED. dag_id=load_rappers_dag_pyop, task_id=load_rappers_to_gcs, execution_date=20221015T211909, start_date=20221015T211924, end_date=20221015T211926
[2022-10-15 21:19:26,306] {standard_task_runner.py:97} ERROR - Failed to execute job 26 for task load_rappers_to_gcs (403 POST https://storage.googleapis.com/upload/storage/v1/b/raw_battle_rap/o?uploadType=multipart: {
  "error": {
    "code": 403,
    "message": "sqlalchemy@battle-rap-365403.iam.gserviceaccount.com does not have storage.objects.create access to the Google Cloud Storage object.",
    "errors": [
      {
        "message": "sqlalchemy@battle-rap-365403.iam.gserviceaccount.com does not have storage.objects.create access to the Google Cloud Storage object.",
        "domain": "global",
        "reason": "forbidden"
      }
    ]
  }
}
: ('Request failed with status code', 403, 'Expected one of', <HTTPStatus.OK: 200>); 5933)
[2022-10-15 21:19:26,334] {local_task_job.py:156} INFO - Task exited with return code 1
[2022-10-15 21:19:26,381] {local_task_job.py:273} INFO - 0 downstream tasks scheduled from follow-on schedule check
