[2022-10-07 17:23:09,558] {taskinstance.py:1159} INFO - Dependencies all met for <TaskInstance: load_rappers_dag.load_rappers scheduled__2022-10-07T14:00:00+00:00 [queued]>
[2022-10-07 17:23:09,601] {taskinstance.py:1159} INFO - Dependencies all met for <TaskInstance: load_rappers_dag.load_rappers scheduled__2022-10-07T14:00:00+00:00 [queued]>
[2022-10-07 17:23:09,601] {taskinstance.py:1356} INFO - 
--------------------------------------------------------------------------------
[2022-10-07 17:23:09,602] {taskinstance.py:1357} INFO - Starting attempt 1 of 1
[2022-10-07 17:23:09,602] {taskinstance.py:1358} INFO - 
--------------------------------------------------------------------------------
[2022-10-07 17:23:09,682] {taskinstance.py:1377} INFO - Executing <Task(BashOperator): load_rappers> on 2022-10-07 14:00:00+00:00
[2022-10-07 17:23:09,689] {standard_task_runner.py:52} INFO - Started process 2315 to run task
[2022-10-07 17:23:09,701] {standard_task_runner.py:79} INFO - Running: ['***', 'tasks', 'run', 'load_rappers_dag', 'load_rappers', 'scheduled__2022-10-07T14:00:00+00:00', '--job-id', '65', '--raw', '--subdir', 'DAGS_FOLDER/load_rappers_dag.py', '--cfg-path', '/tmp/tmpc86r0nle', '--error-file', '/tmp/tmpbs0gf_9u']
[2022-10-07 17:23:09,706] {standard_task_runner.py:80} INFO - Job 65: Subtask load_rappers
[2022-10-07 17:23:09,938] {task_command.py:369} INFO - Running <TaskInstance: load_rappers_dag.load_rappers scheduled__2022-10-07T14:00:00+00:00 [running]> on host 84650b6b2dfc
[2022-10-07 17:23:10,308] {taskinstance.py:1571} INFO - Exporting the following env vars:
AIRFLOW_CTX_DAG_OWNER=***
AIRFLOW_CTX_DAG_ID=load_rappers_dag
AIRFLOW_CTX_TASK_ID=load_rappers
AIRFLOW_CTX_EXECUTION_DATE=2022-10-07T14:00:00+00:00
AIRFLOW_CTX_TRY_NUMBER=1
AIRFLOW_CTX_DAG_RUN_ID=scheduled__2022-10-07T14:00:00+00:00
[2022-10-07 17:23:10,310] {subprocess.py:62} INFO - Tmp dir root location: 
 /tmp
[2022-10-07 17:23:10,316] {subprocess.py:74} INFO - Running command: ['bash', '-c', 'python ${AIRFLOW_HOME}/scripts/load_rappers.py']
[2022-10-07 17:23:10,351] {subprocess.py:85} INFO - Output:
[2022-10-07 17:28:15,005] {subprocess.py:92} INFO - Compiling artist list...
[2022-10-07 17:28:15,034] {subprocess.py:92} INFO - Loading artists...
[2022-10-07 17:28:15,034] {subprocess.py:92} INFO - 505 artists loaded in 125.17 seconds
[2022-10-07 17:28:15,034] {subprocess.py:92} INFO - Loading tracks...
[2022-10-07 17:28:15,034] {subprocess.py:92} INFO - 2506 tracks loaded in 132.31 seconds
[2022-10-07 17:28:15,034] {subprocess.py:92} INFO - Loading dataframes to Postgres...
[2022-10-07 17:28:15,035] {subprocess.py:92} INFO - Traceback (most recent call last):
[2022-10-07 17:28:15,035] {subprocess.py:92} INFO -   File "/home/***/.local/lib/python3.7/site-packages/sqlalchemy/engine/base.py", line 3141, in _wrap_pool_connect
[2022-10-07 17:28:15,035] {subprocess.py:92} INFO -     return fn()
[2022-10-07 17:28:15,035] {subprocess.py:92} INFO -   File "/home/***/.local/lib/python3.7/site-packages/sqlalchemy/pool/base.py", line 301, in connect
[2022-10-07 17:28:15,035] {subprocess.py:92} INFO -     return _ConnectionFairy._checkout(self)
[2022-10-07 17:28:15,035] {subprocess.py:92} INFO -   File "/home/***/.local/lib/python3.7/site-packages/sqlalchemy/pool/base.py", line 755, in _checkout
[2022-10-07 17:28:15,035] {subprocess.py:92} INFO -     fairy = _ConnectionRecord.checkout(pool)
[2022-10-07 17:28:15,035] {subprocess.py:92} INFO -   File "/home/***/.local/lib/python3.7/site-packages/sqlalchemy/pool/base.py", line 419, in checkout
[2022-10-07 17:28:15,035] {subprocess.py:92} INFO -     rec = pool._do_get()
[2022-10-07 17:28:15,035] {subprocess.py:92} INFO -   File "/home/***/.local/lib/python3.7/site-packages/sqlalchemy/pool/impl.py", line 145, in _do_get
[2022-10-07 17:28:15,035] {subprocess.py:92} INFO -     self._dec_overflow()
[2022-10-07 17:28:15,035] {subprocess.py:92} INFO -   File "/home/***/.local/lib/python3.7/site-packages/sqlalchemy/util/langhelpers.py", line 72, in __exit__
[2022-10-07 17:28:15,035] {subprocess.py:92} INFO -     with_traceback=exc_tb,
[2022-10-07 17:28:15,035] {subprocess.py:92} INFO -   File "/home/***/.local/lib/python3.7/site-packages/sqlalchemy/util/compat.py", line 211, in raise_
[2022-10-07 17:28:15,035] {subprocess.py:92} INFO -     raise exception
[2022-10-07 17:28:15,035] {subprocess.py:92} INFO -   File "/home/***/.local/lib/python3.7/site-packages/sqlalchemy/pool/impl.py", line 142, in _do_get
[2022-10-07 17:28:15,035] {subprocess.py:92} INFO -     return self._create_connection()
[2022-10-07 17:28:15,035] {subprocess.py:92} INFO -   File "/home/***/.local/lib/python3.7/site-packages/sqlalchemy/pool/base.py", line 247, in _create_connection
[2022-10-07 17:28:15,035] {subprocess.py:92} INFO -     return _ConnectionRecord(self)
[2022-10-07 17:28:15,035] {subprocess.py:92} INFO -   File "/home/***/.local/lib/python3.7/site-packages/sqlalchemy/pool/base.py", line 362, in __init__
[2022-10-07 17:28:15,035] {subprocess.py:92} INFO -     self.__connect(first_connect_check=True)
[2022-10-07 17:28:15,035] {subprocess.py:92} INFO -   File "/home/***/.local/lib/python3.7/site-packages/sqlalchemy/pool/base.py", line 605, in __connect
[2022-10-07 17:28:15,035] {subprocess.py:92} INFO -     pool.logger.debug("Error on connect(): %s", e)
[2022-10-07 17:28:15,035] {subprocess.py:92} INFO -   File "/home/***/.local/lib/python3.7/site-packages/sqlalchemy/util/langhelpers.py", line 72, in __exit__
[2022-10-07 17:28:15,035] {subprocess.py:92} INFO -     with_traceback=exc_tb,
[2022-10-07 17:28:15,035] {subprocess.py:92} INFO -   File "/home/***/.local/lib/python3.7/site-packages/sqlalchemy/util/compat.py", line 211, in raise_
[2022-10-07 17:28:15,035] {subprocess.py:92} INFO -     raise exception
[2022-10-07 17:28:15,035] {subprocess.py:92} INFO -   File "/home/***/.local/lib/python3.7/site-packages/sqlalchemy/pool/base.py", line 599, in __connect
[2022-10-07 17:28:15,036] {subprocess.py:92} INFO -     connection = pool._invoke_creator(self)
[2022-10-07 17:28:15,036] {subprocess.py:92} INFO -   File "/home/***/.local/lib/python3.7/site-packages/sqlalchemy/engine/create.py", line 578, in connect
[2022-10-07 17:28:15,036] {subprocess.py:92} INFO -     return dialect.connect(*cargs, **cparams)
[2022-10-07 17:28:15,036] {subprocess.py:92} INFO -   File "/home/***/.local/lib/python3.7/site-packages/sqlalchemy/engine/default.py", line 583, in connect
[2022-10-07 17:28:15,036] {subprocess.py:92} INFO -     return self.dbapi.connect(*cargs, **cparams)
[2022-10-07 17:28:15,036] {subprocess.py:92} INFO -   File "/home/***/.local/lib/python3.7/site-packages/psycopg2/__init__.py", line 122, in connect
[2022-10-07 17:28:15,036] {subprocess.py:92} INFO -     conn = _connect(dsn, connection_factory=connection_factory, **kwasync)
[2022-10-07 17:28:15,036] {subprocess.py:92} INFO - psycopg2.OperationalError: connection to server at "127.0.0.1", port 5555 failed: Connection refused
[2022-10-07 17:28:15,036] {subprocess.py:92} INFO - 	Is the server running on that host and accepting TCP/IP connections?
[2022-10-07 17:28:15,036] {subprocess.py:92} INFO - 
[2022-10-07 17:28:15,036] {subprocess.py:92} INFO - 
[2022-10-07 17:28:15,036] {subprocess.py:92} INFO - The above exception was the direct cause of the following exception:
[2022-10-07 17:28:15,036] {subprocess.py:92} INFO - 
[2022-10-07 17:28:15,036] {subprocess.py:92} INFO - Traceback (most recent call last):
[2022-10-07 17:28:15,036] {subprocess.py:92} INFO -   File "/opt/***/scripts/load_rappers.py", line 82, in <module>
[2022-10-07 17:28:15,036] {subprocess.py:92} INFO -     main()
[2022-10-07 17:28:15,036] {subprocess.py:92} INFO -   File "/opt/***/scripts/load_rappers.py", line 78, in main
[2022-10-07 17:28:15,036] {subprocess.py:92} INFO -     load_to_db(dfRappers, dfTopTracks, engine)
[2022-10-07 17:28:15,036] {subprocess.py:92} INFO -   File "/opt/***/scripts/load_rappers.py", line 68, in load_to_db
[2022-10-07 17:28:15,036] {subprocess.py:92} INFO -     dfRappers.to_sql('rappers', engine, if_exists='replace')
[2022-10-07 17:28:15,036] {subprocess.py:92} INFO -   File "/home/***/.local/lib/python3.7/site-packages/pandas/core/generic.py", line 2882, in to_sql
[2022-10-07 17:28:15,036] {subprocess.py:92} INFO -     method=method,
[2022-10-07 17:28:15,036] {subprocess.py:92} INFO -   File "/home/***/.local/lib/python3.7/site-packages/pandas/io/sql.py", line 728, in to_sql
[2022-10-07 17:28:15,036] {subprocess.py:92} INFO -     **engine_kwargs,
[2022-10-07 17:28:15,037] {subprocess.py:92} INFO -   File "/home/***/.local/lib/python3.7/site-packages/pandas/io/sql.py", line 1758, in to_sql
[2022-10-07 17:28:15,037] {subprocess.py:92} INFO -     dtype=dtype,
[2022-10-07 17:28:15,037] {subprocess.py:92} INFO -   File "/home/***/.local/lib/python3.7/site-packages/pandas/io/sql.py", line 1650, in prep_table
[2022-10-07 17:28:15,037] {subprocess.py:92} INFO -     table.create()
[2022-10-07 17:28:15,037] {subprocess.py:92} INFO -   File "/home/***/.local/lib/python3.7/site-packages/pandas/io/sql.py", line 856, in create
[2022-10-07 17:28:15,037] {subprocess.py:92} INFO -     if self.exists():
[2022-10-07 17:28:15,037] {subprocess.py:92} INFO -   File "/home/***/.local/lib/python3.7/site-packages/pandas/io/sql.py", line 840, in exists
[2022-10-07 17:28:15,037] {subprocess.py:92} INFO -     return self.pd_sql.has_table(self.name, self.schema)
[2022-10-07 17:28:15,037] {subprocess.py:92} INFO -   File "/home/***/.local/lib/python3.7/site-packages/pandas/io/sql.py", line 1783, in has_table
[2022-10-07 17:28:15,037] {subprocess.py:92} INFO -     insp = sa.inspect(self.connectable)
[2022-10-07 17:28:15,037] {subprocess.py:92} INFO -   File "/home/***/.local/lib/python3.7/site-packages/sqlalchemy/inspection.py", line 64, in inspect
[2022-10-07 17:28:15,037] {subprocess.py:92} INFO -     ret = reg(subject)
[2022-10-07 17:28:15,037] {subprocess.py:92} INFO -   File "/home/***/.local/lib/python3.7/site-packages/sqlalchemy/engine/reflection.py", line 182, in _engine_insp
[2022-10-07 17:28:15,037] {subprocess.py:92} INFO -     return Inspector._construct(Inspector._init_engine, bind)
[2022-10-07 17:28:15,037] {subprocess.py:92} INFO -   File "/home/***/.local/lib/python3.7/site-packages/sqlalchemy/engine/reflection.py", line 117, in _construct
[2022-10-07 17:28:15,037] {subprocess.py:92} INFO -     init(self, bind)
[2022-10-07 17:28:15,037] {subprocess.py:92} INFO -   File "/home/***/.local/lib/python3.7/site-packages/sqlalchemy/engine/reflection.py", line 128, in _init_engine
[2022-10-07 17:28:15,037] {subprocess.py:92} INFO -     engine.connect().close()
[2022-10-07 17:28:15,037] {subprocess.py:92} INFO -   File "/home/***/.local/lib/python3.7/site-packages/sqlalchemy/engine/base.py", line 3095, in connect
[2022-10-07 17:28:15,037] {subprocess.py:92} INFO -     return self._connection_cls(self, close_with_result=close_with_result)
[2022-10-07 17:28:15,037] {subprocess.py:92} INFO -   File "/home/***/.local/lib/python3.7/site-packages/sqlalchemy/engine/base.py", line 91, in __init__
[2022-10-07 17:28:15,037] {subprocess.py:92} INFO -     else engine.raw_connection()
[2022-10-07 17:28:15,037] {subprocess.py:92} INFO -   File "/home/***/.local/lib/python3.7/site-packages/sqlalchemy/engine/base.py", line 3174, in raw_connection
[2022-10-07 17:28:15,037] {subprocess.py:92} INFO -     return self._wrap_pool_connect(self.pool.connect, _connection)
[2022-10-07 17:28:15,037] {subprocess.py:92} INFO -   File "/home/***/.local/lib/python3.7/site-packages/sqlalchemy/engine/base.py", line 3145, in _wrap_pool_connect
[2022-10-07 17:28:15,037] {subprocess.py:92} INFO -     e, dialect, self
[2022-10-07 17:28:15,037] {subprocess.py:92} INFO -   File "/home/***/.local/lib/python3.7/site-packages/sqlalchemy/engine/base.py", line 2004, in _handle_dbapi_exception_noconnection
[2022-10-07 17:28:15,037] {subprocess.py:92} INFO -     sqlalchemy_exception, with_traceback=exc_info[2], from_=e
[2022-10-07 17:28:15,037] {subprocess.py:92} INFO -   File "/home/***/.local/lib/python3.7/site-packages/sqlalchemy/util/compat.py", line 211, in raise_
[2022-10-07 17:28:15,037] {subprocess.py:92} INFO -     raise exception
[2022-10-07 17:28:15,037] {subprocess.py:92} INFO -   File "/home/***/.local/lib/python3.7/site-packages/sqlalchemy/engine/base.py", line 3141, in _wrap_pool_connect
[2022-10-07 17:28:15,038] {subprocess.py:92} INFO -     return fn()
[2022-10-07 17:28:15,038] {subprocess.py:92} INFO -   File "/home/***/.local/lib/python3.7/site-packages/sqlalchemy/pool/base.py", line 301, in connect
[2022-10-07 17:28:15,038] {subprocess.py:92} INFO -     return _ConnectionFairy._checkout(self)
[2022-10-07 17:28:15,038] {subprocess.py:92} INFO -   File "/home/***/.local/lib/python3.7/site-packages/sqlalchemy/pool/base.py", line 755, in _checkout
[2022-10-07 17:28:15,038] {subprocess.py:92} INFO -     fairy = _ConnectionRecord.checkout(pool)
[2022-10-07 17:28:15,038] {subprocess.py:92} INFO -   File "/home/***/.local/lib/python3.7/site-packages/sqlalchemy/pool/base.py", line 419, in checkout
[2022-10-07 17:28:15,038] {subprocess.py:92} INFO -     rec = pool._do_get()
[2022-10-07 17:28:15,038] {subprocess.py:92} INFO -   File "/home/***/.local/lib/python3.7/site-packages/sqlalchemy/pool/impl.py", line 145, in _do_get
[2022-10-07 17:28:15,038] {subprocess.py:92} INFO -     self._dec_overflow()
[2022-10-07 17:28:15,038] {subprocess.py:92} INFO -   File "/home/***/.local/lib/python3.7/site-packages/sqlalchemy/util/langhelpers.py", line 72, in __exit__
[2022-10-07 17:28:15,038] {subprocess.py:92} INFO -     with_traceback=exc_tb,
[2022-10-07 17:28:15,038] {subprocess.py:92} INFO -   File "/home/***/.local/lib/python3.7/site-packages/sqlalchemy/util/compat.py", line 211, in raise_
[2022-10-07 17:28:15,038] {subprocess.py:92} INFO -     raise exception
[2022-10-07 17:28:15,038] {subprocess.py:92} INFO -   File "/home/***/.local/lib/python3.7/site-packages/sqlalchemy/pool/impl.py", line 142, in _do_get
[2022-10-07 17:28:15,038] {subprocess.py:92} INFO -     return self._create_connection()
[2022-10-07 17:28:15,038] {subprocess.py:92} INFO -   File "/home/***/.local/lib/python3.7/site-packages/sqlalchemy/pool/base.py", line 247, in _create_connection
[2022-10-07 17:28:15,038] {subprocess.py:92} INFO -     return _ConnectionRecord(self)
[2022-10-07 17:28:15,038] {subprocess.py:92} INFO -   File "/home/***/.local/lib/python3.7/site-packages/sqlalchemy/pool/base.py", line 362, in __init__
[2022-10-07 17:28:15,038] {subprocess.py:92} INFO -     self.__connect(first_connect_check=True)
[2022-10-07 17:28:15,038] {subprocess.py:92} INFO -   File "/home/***/.local/lib/python3.7/site-packages/sqlalchemy/pool/base.py", line 605, in __connect
[2022-10-07 17:28:15,038] {subprocess.py:92} INFO -     pool.logger.debug("Error on connect(): %s", e)
[2022-10-07 17:28:15,038] {subprocess.py:92} INFO -   File "/home/***/.local/lib/python3.7/site-packages/sqlalchemy/util/langhelpers.py", line 72, in __exit__
[2022-10-07 17:28:15,038] {subprocess.py:92} INFO -     with_traceback=exc_tb,
[2022-10-07 17:28:15,038] {subprocess.py:92} INFO -   File "/home/***/.local/lib/python3.7/site-packages/sqlalchemy/util/compat.py", line 211, in raise_
[2022-10-07 17:28:15,038] {subprocess.py:92} INFO -     raise exception
[2022-10-07 17:28:15,038] {subprocess.py:92} INFO -   File "/home/***/.local/lib/python3.7/site-packages/sqlalchemy/pool/base.py", line 599, in __connect
[2022-10-07 17:28:15,038] {subprocess.py:92} INFO -     connection = pool._invoke_creator(self)
[2022-10-07 17:28:15,038] {subprocess.py:92} INFO -   File "/home/***/.local/lib/python3.7/site-packages/sqlalchemy/engine/create.py", line 578, in connect
[2022-10-07 17:28:15,039] {subprocess.py:92} INFO -     return dialect.connect(*cargs, **cparams)
[2022-10-07 17:28:15,039] {subprocess.py:92} INFO -   File "/home/***/.local/lib/python3.7/site-packages/sqlalchemy/engine/default.py", line 583, in connect
[2022-10-07 17:28:15,039] {subprocess.py:92} INFO -     return self.dbapi.connect(*cargs, **cparams)
[2022-10-07 17:28:15,039] {subprocess.py:92} INFO -   File "/home/***/.local/lib/python3.7/site-packages/psycopg2/__init__.py", line 122, in connect
[2022-10-07 17:28:15,039] {subprocess.py:92} INFO -     conn = _connect(dsn, connection_factory=connection_factory, **kwasync)
[2022-10-07 17:28:15,039] {subprocess.py:92} INFO - sqlalchemy.exc.OperationalError: (psycopg2.OperationalError) connection to server at "127.0.0.1", port 5555 failed: Connection refused
[2022-10-07 17:28:15,039] {subprocess.py:92} INFO - 	Is the server running on that host and accepting TCP/IP connections?
[2022-10-07 17:28:15,039] {subprocess.py:92} INFO - 
[2022-10-07 17:28:15,039] {subprocess.py:92} INFO - (Background on this error at: http://sqlalche.me/e/14/e3q8)
[2022-10-07 17:28:15,279] {subprocess.py:96} INFO - Command exited with return code 1
[2022-10-07 17:28:15,525] {taskinstance.py:1889} ERROR - Task failed with exception
Traceback (most recent call last):
  File "/home/airflow/.local/lib/python3.7/site-packages/airflow/operators/bash.py", line 195, in execute
    f'Bash command failed. The command returned a non-zero exit code {result.exit_code}.'
airflow.exceptions.AirflowException: Bash command failed. The command returned a non-zero exit code 1.
[2022-10-07 17:28:15,555] {taskinstance.py:1400} INFO - Marking task as FAILED. dag_id=load_rappers_dag, task_id=load_rappers, execution_date=20221007T140000, start_date=20221007T172309, end_date=20221007T172815
[2022-10-07 17:28:15,637] {standard_task_runner.py:97} ERROR - Failed to execute job 65 for task load_rappers (Bash command failed. The command returned a non-zero exit code 1.; 2315)
[2022-10-07 17:28:15,689] {local_task_job.py:156} INFO - Task exited with return code 1
[2022-10-07 17:28:15,863] {local_task_job.py:273} INFO - 0 downstream tasks scheduled from follow-on schedule check
