[2022-10-15 21:14:32,253] {taskinstance.py:1159} INFO - Dependencies all met for <TaskInstance: load_rappers_dag_pyop.load_tracks_to_gcs manual__2022-10-15T21:14:16.996751+00:00 [queued]>
[2022-10-15 21:14:32,264] {taskinstance.py:1159} INFO - Dependencies all met for <TaskInstance: load_rappers_dag_pyop.load_tracks_to_gcs manual__2022-10-15T21:14:16.996751+00:00 [queued]>
[2022-10-15 21:14:32,264] {taskinstance.py:1356} INFO - 
--------------------------------------------------------------------------------
[2022-10-15 21:14:32,264] {taskinstance.py:1357} INFO - Starting attempt 1 of 1
[2022-10-15 21:14:32,264] {taskinstance.py:1358} INFO - 
--------------------------------------------------------------------------------
[2022-10-15 21:14:32,278] {taskinstance.py:1377} INFO - Executing <Task(PostgresToGCSOperator): load_tracks_to_gcs> on 2022-10-15 21:14:16.996751+00:00
[2022-10-15 21:14:32,284] {standard_task_runner.py:52} INFO - Started process 5806 to run task
[2022-10-15 21:14:32,288] {standard_task_runner.py:79} INFO - Running: ['***', 'tasks', 'run', 'load_rappers_dag_pyop', 'load_tracks_to_gcs', 'manual__2022-10-15T21:14:16.996751+00:00', '--job-id', '21', '--raw', '--subdir', 'DAGS_FOLDER/load_rappers_dag_pyop.py', '--cfg-path', '/tmp/tmp2ibem090', '--error-file', '/tmp/tmppnvzym_x']
[2022-10-15 21:14:32,289] {standard_task_runner.py:80} INFO - Job 21: Subtask load_tracks_to_gcs
[2022-10-15 21:14:32,349] {task_command.py:369} INFO - Running <TaskInstance: load_rappers_dag_pyop.load_tracks_to_gcs manual__2022-10-15T21:14:16.996751+00:00 [running]> on host 6300e87c6973
[2022-10-15 21:14:32,426] {taskinstance.py:1571} INFO - Exporting the following env vars:
AIRFLOW_CTX_DAG_OWNER=***
AIRFLOW_CTX_DAG_ID=load_rappers_dag_pyop
AIRFLOW_CTX_TASK_ID=load_tracks_to_gcs
AIRFLOW_CTX_EXECUTION_DATE=2022-10-15T21:14:16.996751+00:00
AIRFLOW_CTX_TRY_NUMBER=1
AIRFLOW_CTX_DAG_RUN_ID=manual__2022-10-15T21:14:16.996751+00:00
[2022-10-15 21:14:32,427] {sql_to_gcs.py:139} INFO - Executing query
[2022-10-15 21:14:32,438] {base.py:68} INFO - Using connection ID 'postgres-dc' for task execution.
[2022-10-15 21:14:32,459] {sql_to_gcs.py:155} INFO - Writing local data files
[2022-10-15 21:14:32,463] {sql_to_gcs.py:160} INFO - Uploading chunk file #0 to GCS.
[2022-10-15 21:14:32,470] {base.py:68} INFO - Using connection ID 'google_cloud_default' for task execution.
[2022-10-15 21:14:32,488] {taskinstance.py:1889} ERROR - Task failed with exception
Traceback (most recent call last):
  File "/home/airflow/.local/lib/python3.7/site-packages/airflow/providers/google/cloud/transfers/sql_to_gcs.py", line 161, in execute
    self._upload_to_gcs(file_to_upload)
  File "/home/airflow/.local/lib/python3.7/site-packages/airflow/providers/google/cloud/transfers/sql_to_gcs.py", line 358, in _upload_to_gcs
    gzip=self.gzip if file_to_upload.get('file_name') != self.schema_filename else False,
  File "/home/airflow/.local/lib/python3.7/site-packages/airflow/providers/google/cloud/hooks/gcs.py", line 495, in upload
    client = self.get_conn()
  File "/home/airflow/.local/lib/python3.7/site-packages/airflow/providers/google/cloud/hooks/gcs.py", line 159, in get_conn
    credentials=self._get_credentials(), client_info=CLIENT_INFO, project=self.project_id
  File "/home/airflow/.local/lib/python3.7/site-packages/airflow/providers/google/common/hooks/base_google.py", line 261, in _get_credentials
    credentials, _ = self._get_credentials_and_project_id()
  File "/home/airflow/.local/lib/python3.7/site-packages/airflow/providers/google/common/hooks/base_google.py", line 247, in _get_credentials_and_project_id
    delegates=delegates,
  File "/home/airflow/.local/lib/python3.7/site-packages/airflow/providers/google/cloud/utils/credentials_provider.py", line 321, in get_credentials_and_project_id
    return _CredentialProvider(*args, **kwargs).get_credentials_and_project()
  File "/home/airflow/.local/lib/python3.7/site-packages/airflow/providers/google/cloud/utils/credentials_provider.py", line 204, in __init__
    "The `keyfile_dict`, `key_path`, and `key_secret_name` fields"
airflow.exceptions.AirflowException: The `keyfile_dict`, `key_path`, and `key_secret_name` fieldsare all mutually exclusive. Please provide only one value.
[2022-10-15 21:14:32,492] {taskinstance.py:1400} INFO - Marking task as FAILED. dag_id=load_rappers_dag_pyop, task_id=load_tracks_to_gcs, execution_date=20221015T211416, start_date=20221015T211432, end_date=20221015T211432
[2022-10-15 21:14:32,502] {standard_task_runner.py:97} ERROR - Failed to execute job 21 for task load_tracks_to_gcs (The `keyfile_dict`, `key_path`, and `key_secret_name` fieldsare all mutually exclusive. Please provide only one value.; 5806)
[2022-10-15 21:14:32,541] {local_task_job.py:156} INFO - Task exited with return code 1
[2022-10-15 21:14:32,577] {local_task_job.py:273} INFO - 0 downstream tasks scheduled from follow-on schedule check
