[2022-10-05 18:26:52,862] {taskinstance.py:1159} INFO - Dependencies all met for <TaskInstance: load_rappers_dag.load_rappers manual__2022-10-05T18:26:50.950234+00:00 [queued]>
[2022-10-05 18:26:52,886] {taskinstance.py:1159} INFO - Dependencies all met for <TaskInstance: load_rappers_dag.load_rappers manual__2022-10-05T18:26:50.950234+00:00 [queued]>
[2022-10-05 18:26:52,886] {taskinstance.py:1356} INFO - 
--------------------------------------------------------------------------------
[2022-10-05 18:26:52,886] {taskinstance.py:1357} INFO - Starting attempt 1 of 1
[2022-10-05 18:26:52,886] {taskinstance.py:1358} INFO - 
--------------------------------------------------------------------------------
[2022-10-05 18:26:52,910] {taskinstance.py:1377} INFO - Executing <Task(BashOperator): load_rappers> on 2022-10-05 18:26:50.950234+00:00
[2022-10-05 18:26:52,913] {standard_task_runner.py:52} INFO - Started process 346 to run task
[2022-10-05 18:26:52,915] {standard_task_runner.py:79} INFO - Running: ['***', 'tasks', 'run', 'load_rappers_dag', 'load_rappers', 'manual__2022-10-05T18:26:50.950234+00:00', '--job-id', '30', '--raw', '--subdir', 'DAGS_FOLDER/load_rappers_dag.py', '--cfg-path', '/tmp/tmp2p9t_3xn', '--error-file', '/tmp/tmp0ndhzh4s']
[2022-10-05 18:26:52,916] {standard_task_runner.py:80} INFO - Job 30: Subtask load_rappers
[2022-10-05 18:26:53,007] {task_command.py:369} INFO - Running <TaskInstance: load_rappers_dag.load_rappers manual__2022-10-05T18:26:50.950234+00:00 [running]> on host 39b88b75de04
[2022-10-05 18:26:53,092] {taskinstance.py:1571} INFO - Exporting the following env vars:
AIRFLOW_CTX_DAG_OWNER=***
AIRFLOW_CTX_DAG_ID=load_rappers_dag
AIRFLOW_CTX_TASK_ID=load_rappers
AIRFLOW_CTX_EXECUTION_DATE=2022-10-05T18:26:50.950234+00:00
AIRFLOW_CTX_TRY_NUMBER=1
AIRFLOW_CTX_DAG_RUN_ID=manual__2022-10-05T18:26:50.950234+00:00
[2022-10-05 18:26:53,093] {subprocess.py:62} INFO - Tmp dir root location: 
 /tmp
[2022-10-05 18:26:53,094] {subprocess.py:74} INFO - Running command: ['bash', '-c', 'python ${AIRFLOW_HOME}/scripts/load_rappers.py']
[2022-10-05 18:26:53,101] {subprocess.py:85} INFO - Output:
[2022-10-05 18:32:22,762] {subprocess.py:92} INFO - Compiling artist list...
[2022-10-05 18:32:22,784] {subprocess.py:92} INFO - Loading artists...
[2022-10-05 18:32:22,784] {subprocess.py:92} INFO - 502 artists loaded in 162.60 seconds
[2022-10-05 18:32:22,784] {subprocess.py:92} INFO - Loading tracks...
[2022-10-05 18:32:22,784] {subprocess.py:92} INFO - 2497 tracks loaded in 150.62 seconds
[2022-10-05 18:32:22,784] {subprocess.py:92} INFO - Traceback (most recent call last):
[2022-10-05 18:32:22,784] {subprocess.py:92} INFO -   File "/opt/***/scripts/load_rappers.py", line 58, in <module>
[2022-10-05 18:32:22,785] {subprocess.py:92} INFO -     dfRappers.to_csv("data/rappers_data.csv") # test
[2022-10-05 18:32:22,785] {subprocess.py:92} INFO -   File "/home/***/.local/lib/python3.7/site-packages/pandas/core/generic.py", line 3482, in to_csv
[2022-10-05 18:32:22,785] {subprocess.py:92} INFO -     storage_options=storage_options,
[2022-10-05 18:32:22,785] {subprocess.py:92} INFO -   File "/home/***/.local/lib/python3.7/site-packages/pandas/io/formats/format.py", line 1105, in to_csv
[2022-10-05 18:32:22,785] {subprocess.py:92} INFO -     csv_formatter.save()
[2022-10-05 18:32:22,785] {subprocess.py:92} INFO -   File "/home/***/.local/lib/python3.7/site-packages/pandas/io/formats/csvs.py", line 243, in save
[2022-10-05 18:32:22,785] {subprocess.py:92} INFO -     storage_options=self.storage_options,
[2022-10-05 18:32:22,785] {subprocess.py:92} INFO -   File "/home/***/.local/lib/python3.7/site-packages/pandas/io/common.py", line 707, in get_handle
[2022-10-05 18:32:22,785] {subprocess.py:92} INFO -     newline="",
[2022-10-05 18:32:22,785] {subprocess.py:92} INFO - FileNotFoundError: [Errno 2] No such file or directory: 'data/rappers_data.csv'
[2022-10-05 18:32:23,226] {subprocess.py:96} INFO - Command exited with return code 1
[2022-10-05 18:32:23,346] {taskinstance.py:1889} ERROR - Task failed with exception
Traceback (most recent call last):
  File "/home/airflow/.local/lib/python3.7/site-packages/airflow/operators/bash.py", line 195, in execute
    f'Bash command failed. The command returned a non-zero exit code {result.exit_code}.'
airflow.exceptions.AirflowException: Bash command failed. The command returned a non-zero exit code 1.
[2022-10-05 18:32:23,374] {taskinstance.py:1400} INFO - Marking task as FAILED. dag_id=load_rappers_dag, task_id=load_rappers, execution_date=20221005T182650, start_date=20221005T182652, end_date=20221005T183223
[2022-10-05 18:32:23,426] {standard_task_runner.py:97} ERROR - Failed to execute job 30 for task load_rappers (Bash command failed. The command returned a non-zero exit code 1.; 346)
[2022-10-05 18:32:23,481] {local_task_job.py:156} INFO - Task exited with return code 1
[2022-10-05 18:32:23,557] {local_task_job.py:273} INFO - 0 downstream tasks scheduled from follow-on schedule check
