[2022-10-07 17:21:44,151] {taskinstance.py:1159} INFO - Dependencies all met for <TaskInstance: load_rappers_dag.load_rappers scheduled__2022-10-07T04:00:00+00:00 [queued]>
[2022-10-07 17:21:44,171] {taskinstance.py:1159} INFO - Dependencies all met for <TaskInstance: load_rappers_dag.load_rappers scheduled__2022-10-07T04:00:00+00:00 [queued]>
[2022-10-07 17:21:44,172] {taskinstance.py:1356} INFO - 
--------------------------------------------------------------------------------
[2022-10-07 17:21:44,172] {taskinstance.py:1357} INFO - Starting attempt 1 of 1
[2022-10-07 17:21:44,172] {taskinstance.py:1358} INFO - 
--------------------------------------------------------------------------------
[2022-10-07 17:21:44,237] {taskinstance.py:1377} INFO - Executing <Task(BashOperator): load_rappers> on 2022-10-07 04:00:00+00:00
[2022-10-07 17:21:44,247] {standard_task_runner.py:52} INFO - Started process 2240 to run task
[2022-10-07 17:21:44,258] {standard_task_runner.py:79} INFO - Running: ['***', 'tasks', 'run', 'load_rappers_dag', 'load_rappers', 'scheduled__2022-10-07T04:00:00+00:00', '--job-id', '54', '--raw', '--subdir', 'DAGS_FOLDER/load_rappers_dag.py', '--cfg-path', '/tmp/tmpozitrwnj', '--error-file', '/tmp/tmpt_95y2zz']
[2022-10-07 17:21:44,261] {standard_task_runner.py:80} INFO - Job 54: Subtask load_rappers
[2022-10-07 17:21:44,505] {task_command.py:369} INFO - Running <TaskInstance: load_rappers_dag.load_rappers scheduled__2022-10-07T04:00:00+00:00 [running]> on host 84650b6b2dfc
[2022-10-07 17:21:51,016] {taskinstance.py:1571} INFO - Exporting the following env vars:
AIRFLOW_CTX_DAG_OWNER=***
AIRFLOW_CTX_DAG_ID=load_rappers_dag
AIRFLOW_CTX_TASK_ID=load_rappers
AIRFLOW_CTX_EXECUTION_DATE=2022-10-07T04:00:00+00:00
AIRFLOW_CTX_TRY_NUMBER=1
AIRFLOW_CTX_DAG_RUN_ID=scheduled__2022-10-07T04:00:00+00:00
[2022-10-07 17:21:51,041] {subprocess.py:62} INFO - Tmp dir root location: 
 /tmp
[2022-10-07 17:21:51,095] {subprocess.py:74} INFO - Running command: ['bash', '-c', 'python ${AIRFLOW_HOME}/scripts/load_rappers.py']
[2022-10-07 17:21:51,381] {subprocess.py:85} INFO - Output:
[2022-10-07 17:23:48,813] {base_job.py:229} ERROR - LocalTaskJob heartbeat got an exception
Traceback (most recent call last):
  File "/home/airflow/.local/lib/python3.7/site-packages/sqlalchemy/engine/base.py", line 3141, in _wrap_pool_connect
    return fn()
  File "/home/airflow/.local/lib/python3.7/site-packages/sqlalchemy/pool/base.py", line 301, in connect
    return _ConnectionFairy._checkout(self)
  File "/home/airflow/.local/lib/python3.7/site-packages/sqlalchemy/pool/base.py", line 755, in _checkout
    fairy = _ConnectionRecord.checkout(pool)
  File "/home/airflow/.local/lib/python3.7/site-packages/sqlalchemy/pool/base.py", line 419, in checkout
    rec = pool._do_get()
  File "/home/airflow/.local/lib/python3.7/site-packages/sqlalchemy/pool/impl.py", line 259, in _do_get
    return self._create_connection()
  File "/home/airflow/.local/lib/python3.7/site-packages/sqlalchemy/pool/base.py", line 247, in _create_connection
    return _ConnectionRecord(self)
  File "/home/airflow/.local/lib/python3.7/site-packages/sqlalchemy/pool/base.py", line 362, in __init__
    self.__connect(first_connect_check=True)
  File "/home/airflow/.local/lib/python3.7/site-packages/sqlalchemy/pool/base.py", line 605, in __connect
    pool.logger.debug("Error on connect(): %s", e)
  File "/home/airflow/.local/lib/python3.7/site-packages/sqlalchemy/util/langhelpers.py", line 72, in __exit__
    with_traceback=exc_tb,
  File "/home/airflow/.local/lib/python3.7/site-packages/sqlalchemy/util/compat.py", line 211, in raise_
    raise exception
  File "/home/airflow/.local/lib/python3.7/site-packages/sqlalchemy/pool/base.py", line 599, in __connect
    connection = pool._invoke_creator(self)
  File "/home/airflow/.local/lib/python3.7/site-packages/sqlalchemy/engine/create.py", line 578, in connect
    return dialect.connect(*cargs, **cparams)
  File "/home/airflow/.local/lib/python3.7/site-packages/sqlalchemy/engine/default.py", line 583, in connect
    return self.dbapi.connect(*cargs, **cparams)
  File "/home/airflow/.local/lib/python3.7/site-packages/psycopg2/__init__.py", line 122, in connect
    conn = _connect(dsn, connection_factory=connection_factory, **kwasync)
psycopg2.OperationalError: could not translate host name "postgres" to address: Temporary failure in name resolution


The above exception was the direct cause of the following exception:

Traceback (most recent call last):
  File "/home/airflow/.local/lib/python3.7/site-packages/airflow/jobs/base_job.py", line 201, in heartbeat
    session.merge(self)
  File "/home/airflow/.local/lib/python3.7/site-packages/sqlalchemy/orm/session.py", line 2877, in merge
    _resolve_conflict_map=_resolve_conflict_map,
  File "/home/airflow/.local/lib/python3.7/site-packages/sqlalchemy/orm/session.py", line 2950, in _merge
    merged = self.get(mapper.class_, key[1], identity_token=key[2])
  File "/home/airflow/.local/lib/python3.7/site-packages/sqlalchemy/orm/session.py", line 2702, in get
    identity_token=identity_token,
  File "/home/airflow/.local/lib/python3.7/site-packages/sqlalchemy/orm/session.py", line 2800, in _get_impl
    load_options=load_options,
  File "/home/airflow/.local/lib/python3.7/site-packages/sqlalchemy/orm/loading.py", line 535, in load_on_pk_identity
    bind_arguments=bind_arguments,
  File "/home/airflow/.local/lib/python3.7/site-packages/sqlalchemy/orm/session.py", line 1669, in execute
    conn = self._connection_for_bind(bind, close_with_result=True)
  File "/home/airflow/.local/lib/python3.7/site-packages/sqlalchemy/orm/session.py", line 1520, in _connection_for_bind
    engine, execution_options
  File "/home/airflow/.local/lib/python3.7/site-packages/sqlalchemy/orm/session.py", line 747, in _connection_for_bind
    conn = bind.connect()
  File "/home/airflow/.local/lib/python3.7/site-packages/sqlalchemy/engine/base.py", line 3095, in connect
    return self._connection_cls(self, close_with_result=close_with_result)
  File "/home/airflow/.local/lib/python3.7/site-packages/sqlalchemy/engine/base.py", line 91, in __init__
    else engine.raw_connection()
  File "/home/airflow/.local/lib/python3.7/site-packages/sqlalchemy/engine/base.py", line 3174, in raw_connection
    return self._wrap_pool_connect(self.pool.connect, _connection)
  File "/home/airflow/.local/lib/python3.7/site-packages/sqlalchemy/engine/base.py", line 3145, in _wrap_pool_connect
    e, dialect, self
  File "/home/airflow/.local/lib/python3.7/site-packages/sqlalchemy/engine/base.py", line 2004, in _handle_dbapi_exception_noconnection
    sqlalchemy_exception, with_traceback=exc_info[2], from_=e
  File "/home/airflow/.local/lib/python3.7/site-packages/sqlalchemy/util/compat.py", line 211, in raise_
    raise exception
  File "/home/airflow/.local/lib/python3.7/site-packages/sqlalchemy/engine/base.py", line 3141, in _wrap_pool_connect
    return fn()
  File "/home/airflow/.local/lib/python3.7/site-packages/sqlalchemy/pool/base.py", line 301, in connect
    return _ConnectionFairy._checkout(self)
  File "/home/airflow/.local/lib/python3.7/site-packages/sqlalchemy/pool/base.py", line 755, in _checkout
    fairy = _ConnectionRecord.checkout(pool)
  File "/home/airflow/.local/lib/python3.7/site-packages/sqlalchemy/pool/base.py", line 419, in checkout
    rec = pool._do_get()
  File "/home/airflow/.local/lib/python3.7/site-packages/sqlalchemy/pool/impl.py", line 259, in _do_get
    return self._create_connection()
  File "/home/airflow/.local/lib/python3.7/site-packages/sqlalchemy/pool/base.py", line 247, in _create_connection
    return _ConnectionRecord(self)
  File "/home/airflow/.local/lib/python3.7/site-packages/sqlalchemy/pool/base.py", line 362, in __init__
    self.__connect(first_connect_check=True)
  File "/home/airflow/.local/lib/python3.7/site-packages/sqlalchemy/pool/base.py", line 605, in __connect
    pool.logger.debug("Error on connect(): %s", e)
  File "/home/airflow/.local/lib/python3.7/site-packages/sqlalchemy/util/langhelpers.py", line 72, in __exit__
    with_traceback=exc_tb,
  File "/home/airflow/.local/lib/python3.7/site-packages/sqlalchemy/util/compat.py", line 211, in raise_
    raise exception
  File "/home/airflow/.local/lib/python3.7/site-packages/sqlalchemy/pool/base.py", line 599, in __connect
    connection = pool._invoke_creator(self)
  File "/home/airflow/.local/lib/python3.7/site-packages/sqlalchemy/engine/create.py", line 578, in connect
    return dialect.connect(*cargs, **cparams)
  File "/home/airflow/.local/lib/python3.7/site-packages/sqlalchemy/engine/default.py", line 583, in connect
    return self.dbapi.connect(*cargs, **cparams)
  File "/home/airflow/.local/lib/python3.7/site-packages/psycopg2/__init__.py", line 122, in connect
    conn = _connect(dsn, connection_factory=connection_factory, **kwasync)
sqlalchemy.exc.OperationalError: (psycopg2.OperationalError) could not translate host name "postgres" to address: Temporary failure in name resolution

(Background on this error at: http://sqlalche.me/e/14/e3q8)
[2022-10-07 17:23:49,741] {subprocess.py:92} INFO - Compiling artist list...
[2022-10-07 17:23:49,982] {subprocess.py:92} INFO - Loading artists...
[2022-10-07 17:23:49,983] {subprocess.py:92} INFO - Traceback (most recent call last):
[2022-10-07 17:23:49,983] {subprocess.py:92} INFO -   File "/home/***/.local/lib/python3.7/site-packages/urllib3/connectionpool.py", line 710, in urlopen
[2022-10-07 17:23:49,983] {subprocess.py:92} INFO -     chunked=chunked,
[2022-10-07 17:23:49,983] {subprocess.py:92} INFO -   File "/home/***/.local/lib/python3.7/site-packages/urllib3/connectionpool.py", line 386, in _make_request
[2022-10-07 17:23:49,984] {subprocess.py:92} INFO -     self._validate_conn(conn)
[2022-10-07 17:23:49,984] {subprocess.py:92} INFO -   File "/home/***/.local/lib/python3.7/site-packages/urllib3/connectionpool.py", line 1040, in _validate_conn
[2022-10-07 17:23:49,984] {subprocess.py:92} INFO -     conn.connect()
[2022-10-07 17:23:49,984] {subprocess.py:92} INFO -   File "/home/***/.local/lib/python3.7/site-packages/urllib3/connection.py", line 424, in connect
[2022-10-07 17:23:49,984] {subprocess.py:92} INFO -     tls_in_tls=tls_in_tls,
[2022-10-07 17:23:49,984] {subprocess.py:92} INFO -   File "/home/***/.local/lib/python3.7/site-packages/urllib3/util/ssl_.py", line 450, in ssl_wrap_socket
[2022-10-07 17:23:49,984] {subprocess.py:92} INFO -     sock, context, tls_in_tls, server_hostname=server_hostname
[2022-10-07 17:23:50,001] {subprocess.py:92} INFO -   File "/home/***/.local/lib/python3.7/site-packages/urllib3/util/ssl_.py", line 493, in _ssl_wrap_socket_impl
[2022-10-07 17:23:50,001] {subprocess.py:92} INFO -     return ssl_context.wrap_socket(sock, server_hostname=server_hostname)
[2022-10-07 17:23:50,002] {subprocess.py:92} INFO -   File "/usr/local/lib/python3.7/ssl.py", line 423, in wrap_socket
[2022-10-07 17:23:50,002] {subprocess.py:92} INFO -     session=session
[2022-10-07 17:23:50,003] {subprocess.py:92} INFO -   File "/usr/local/lib/python3.7/ssl.py", line 870, in _create
[2022-10-07 17:23:50,003] {subprocess.py:92} INFO -     self.do_handshake()
[2022-10-07 17:23:50,004] {subprocess.py:92} INFO -   File "/usr/local/lib/python3.7/ssl.py", line 1139, in do_handshake
[2022-10-07 17:23:50,004] {subprocess.py:92} INFO -     self._sslobj.do_handshake()
[2022-10-07 17:23:50,004] {subprocess.py:92} INFO - OSError: [Errno 0] Error
[2022-10-07 17:23:50,004] {subprocess.py:92} INFO - 
[2022-10-07 17:23:50,005] {subprocess.py:92} INFO - During handling of the above exception, another exception occurred:
[2022-10-07 17:23:50,005] {subprocess.py:92} INFO - 
[2022-10-07 17:23:50,006] {subprocess.py:92} INFO - Traceback (most recent call last):
[2022-10-07 17:23:50,007] {subprocess.py:92} INFO -   File "/home/***/.local/lib/python3.7/site-packages/requests/adapters.py", line 450, in send
[2022-10-07 17:23:50,008] {subprocess.py:92} INFO -     timeout=timeout
[2022-10-07 17:23:50,009] {subprocess.py:92} INFO -   File "/home/***/.local/lib/python3.7/site-packages/urllib3/connectionpool.py", line 786, in urlopen
[2022-10-07 17:23:50,013] {subprocess.py:92} INFO -     method, url, error=e, _pool=self, _stacktrace=sys.exc_info()[2]
[2022-10-07 17:23:50,017] {subprocess.py:92} INFO -   File "/home/***/.local/lib/python3.7/site-packages/urllib3/util/retry.py", line 550, in increment
[2022-10-07 17:23:50,017] {subprocess.py:92} INFO -     raise six.reraise(type(error), error, _stacktrace)
[2022-10-07 17:23:50,057] {subprocess.py:92} INFO -   File "/home/***/.local/lib/python3.7/site-packages/urllib3/packages/six.py", line 769, in reraise
[2022-10-07 17:23:50,057] {subprocess.py:92} INFO -     raise value.with_traceback(tb)
[2022-10-07 17:23:50,057] {subprocess.py:92} INFO -   File "/home/***/.local/lib/python3.7/site-packages/urllib3/connectionpool.py", line 710, in urlopen
[2022-10-07 17:23:50,057] {subprocess.py:92} INFO -     chunked=chunked,
[2022-10-07 17:23:50,057] {subprocess.py:92} INFO -   File "/home/***/.local/lib/python3.7/site-packages/urllib3/connectionpool.py", line 386, in _make_request
[2022-10-07 17:23:50,057] {subprocess.py:92} INFO -     self._validate_conn(conn)
[2022-10-07 17:23:50,057] {subprocess.py:92} INFO -   File "/home/***/.local/lib/python3.7/site-packages/urllib3/connectionpool.py", line 1040, in _validate_conn
[2022-10-07 17:23:50,057] {subprocess.py:92} INFO -     conn.connect()
[2022-10-07 17:23:50,058] {subprocess.py:92} INFO -   File "/home/***/.local/lib/python3.7/site-packages/urllib3/connection.py", line 424, in connect
[2022-10-07 17:23:50,058] {subprocess.py:92} INFO -     tls_in_tls=tls_in_tls,
[2022-10-07 17:23:50,058] {subprocess.py:92} INFO -   File "/home/***/.local/lib/python3.7/site-packages/urllib3/util/ssl_.py", line 450, in ssl_wrap_socket
[2022-10-07 17:23:50,063] {subprocess.py:92} INFO -     sock, context, tls_in_tls, server_hostname=server_hostname
[2022-10-07 17:23:50,063] {subprocess.py:92} INFO -   File "/home/***/.local/lib/python3.7/site-packages/urllib3/util/ssl_.py", line 493, in _ssl_wrap_socket_impl
[2022-10-07 17:23:50,063] {subprocess.py:92} INFO -     return ssl_context.wrap_socket(sock, server_hostname=server_hostname)
[2022-10-07 17:23:50,063] {subprocess.py:92} INFO -   File "/usr/local/lib/python3.7/ssl.py", line 423, in wrap_socket
[2022-10-07 17:23:50,063] {subprocess.py:92} INFO -     session=session
[2022-10-07 17:23:50,063] {subprocess.py:92} INFO -   File "/usr/local/lib/python3.7/ssl.py", line 870, in _create
[2022-10-07 17:23:50,063] {subprocess.py:92} INFO -     self.do_handshake()
[2022-10-07 17:23:50,064] {subprocess.py:92} INFO -   File "/usr/local/lib/python3.7/ssl.py", line 1139, in do_handshake
[2022-10-07 17:23:50,064] {subprocess.py:92} INFO -     self._sslobj.do_handshake()
[2022-10-07 17:23:50,064] {subprocess.py:92} INFO - urllib3.exceptions.ProtocolError: ('Connection aborted.', OSError(0, 'Error'))
[2022-10-07 17:23:50,064] {subprocess.py:92} INFO - 
[2022-10-07 17:23:50,064] {subprocess.py:92} INFO - During handling of the above exception, another exception occurred:
[2022-10-07 17:23:50,064] {subprocess.py:92} INFO - 
[2022-10-07 17:23:50,064] {subprocess.py:92} INFO - Traceback (most recent call last):
[2022-10-07 17:23:50,064] {subprocess.py:92} INFO -   File "/opt/***/scripts/load_rappers.py", line 82, in <module>
[2022-10-07 17:23:50,065] {subprocess.py:92} INFO -     main()
[2022-10-07 17:23:50,065] {subprocess.py:92} INFO -   File "/opt/***/scripts/load_rappers.py", line 74, in main
[2022-10-07 17:23:50,065] {subprocess.py:92} INFO -     dfRappers = get_artist_data(lister, combinedArtists)
[2022-10-07 17:23:50,065] {subprocess.py:92} INFO -   File "/opt/***/scripts/load_rappers.py", line 43, in get_artist_data
[2022-10-07 17:23:50,065] {subprocess.py:92} INFO -     dfRappers = pd.DataFrame(lister.pull_artist_data(combinedArtists))
[2022-10-07 17:23:50,065] {subprocess.py:92} INFO -   File "/opt/***/scripts/artist_lister.py", line 49, in pull_artist_data
[2022-10-07 17:23:50,066] {subprocess.py:92} INFO -     payload = self.get_artist(i)
[2022-10-07 17:23:50,066] {subprocess.py:92} INFO -   File "/opt/***/scripts/spotify_client.py", line 96, in get_artist
[2022-10-07 17:23:50,066] {subprocess.py:92} INFO -     return self.get_resource(_id, resource_type='artists')
[2022-10-07 17:23:50,066] {subprocess.py:92} INFO -   File "/opt/***/scripts/spotify_client.py", line 81, in get_resource
[2022-10-07 17:23:50,066] {subprocess.py:92} INFO -     r = requests.get(endpoint, headers=headers)
[2022-10-07 17:23:50,066] {subprocess.py:92} INFO -   File "/home/***/.local/lib/python3.7/site-packages/requests/api.py", line 75, in get
[2022-10-07 17:23:50,066] {subprocess.py:92} INFO -     return request('get', url, params=params, **kwargs)
[2022-10-07 17:23:50,066] {subprocess.py:92} INFO -   File "/home/***/.local/lib/python3.7/site-packages/requests/api.py", line 61, in request
[2022-10-07 17:23:50,067] {subprocess.py:92} INFO -     return session.request(method=method, url=url, **kwargs)
[2022-10-07 17:23:50,067] {subprocess.py:92} INFO -   File "/home/***/.local/lib/python3.7/site-packages/requests/sessions.py", line 529, in request
[2022-10-07 17:23:50,067] {subprocess.py:92} INFO -     resp = self.send(prep, **send_kwargs)
[2022-10-07 17:23:50,067] {subprocess.py:92} INFO -   File "/home/***/.local/lib/python3.7/site-packages/requests/sessions.py", line 645, in send
[2022-10-07 17:23:50,068] {subprocess.py:92} INFO -     r = adapter.send(request, **kwargs)
[2022-10-07 17:23:50,068] {subprocess.py:92} INFO -   File "/home/***/.local/lib/python3.7/site-packages/requests/adapters.py", line 501, in send
[2022-10-07 17:23:50,068] {subprocess.py:92} INFO -     raise ConnectionError(err, request=request)
[2022-10-07 17:23:50,068] {subprocess.py:92} INFO - requests.exceptions.ConnectionError: ('Connection aborted.', OSError(0, 'Error'))
[2022-10-07 17:23:54,942] {subprocess.py:96} INFO - Command exited with return code 1
[2022-10-07 17:23:55,639] {taskinstance.py:1889} ERROR - Task failed with exception
Traceback (most recent call last):
  File "/home/airflow/.local/lib/python3.7/site-packages/airflow/operators/bash.py", line 195, in execute
    f'Bash command failed. The command returned a non-zero exit code {result.exit_code}.'
airflow.exceptions.AirflowException: Bash command failed. The command returned a non-zero exit code 1.
[2022-10-07 17:23:55,674] {taskinstance.py:1400} INFO - Marking task as FAILED. dag_id=load_rappers_dag, task_id=load_rappers, execution_date=20221007T040000, start_date=20221007T172144, end_date=20221007T172355
[2022-10-07 17:23:55,816] {standard_task_runner.py:97} ERROR - Failed to execute job 54 for task load_rappers (Bash command failed. The command returned a non-zero exit code 1.; 2240)
[2022-10-07 17:23:55,851] {local_task_job.py:156} INFO - Task exited with return code 1
[2022-10-07 17:23:56,128] {local_task_job.py:273} INFO - 0 downstream tasks scheduled from follow-on schedule check
