[2022-10-06 02:00:01,977] {taskinstance.py:1159} INFO - Dependencies all met for <TaskInstance: load_rappers_dag.load_rappers scheduled__2022-10-06T01:00:00+00:00 [queued]>
[2022-10-06 02:00:01,987] {taskinstance.py:1159} INFO - Dependencies all met for <TaskInstance: load_rappers_dag.load_rappers scheduled__2022-10-06T01:00:00+00:00 [queued]>
[2022-10-06 02:00:01,987] {taskinstance.py:1356} INFO - 
--------------------------------------------------------------------------------
[2022-10-06 02:00:01,987] {taskinstance.py:1357} INFO - Starting attempt 1 of 1
[2022-10-06 02:00:01,987] {taskinstance.py:1358} INFO - 
--------------------------------------------------------------------------------
[2022-10-06 02:00:02,003] {taskinstance.py:1377} INFO - Executing <Task(BashOperator): load_rappers> on 2022-10-06 01:00:00+00:00
[2022-10-06 02:00:02,006] {standard_task_runner.py:52} INFO - Started process 8757 to run task
[2022-10-06 02:00:02,008] {standard_task_runner.py:79} INFO - Running: ['***', 'tasks', 'run', 'load_rappers_dag', 'load_rappers', 'scheduled__2022-10-06T01:00:00+00:00', '--job-id', '43', '--raw', '--subdir', 'DAGS_FOLDER/load_rappers_dag.py', '--cfg-path', '/tmp/tmpb9011t2o', '--error-file', '/tmp/tmpvm89qyqh']
[2022-10-06 02:00:02,009] {standard_task_runner.py:80} INFO - Job 43: Subtask load_rappers
[2022-10-06 02:00:02,059] {task_command.py:369} INFO - Running <TaskInstance: load_rappers_dag.load_rappers scheduled__2022-10-06T01:00:00+00:00 [running]> on host 39b88b75de04
[2022-10-06 02:00:02,138] {taskinstance.py:1571} INFO - Exporting the following env vars:
AIRFLOW_CTX_DAG_OWNER=***
AIRFLOW_CTX_DAG_ID=load_rappers_dag
AIRFLOW_CTX_TASK_ID=load_rappers
AIRFLOW_CTX_EXECUTION_DATE=2022-10-06T01:00:00+00:00
AIRFLOW_CTX_TRY_NUMBER=1
AIRFLOW_CTX_DAG_RUN_ID=scheduled__2022-10-06T01:00:00+00:00
[2022-10-06 02:00:02,140] {subprocess.py:62} INFO - Tmp dir root location: 
 /tmp
[2022-10-06 02:00:02,141] {subprocess.py:74} INFO - Running command: ['bash', '-c', 'python ${AIRFLOW_HOME}/scripts/load_rappers.py']
[2022-10-06 02:00:02,148] {subprocess.py:85} INFO - Output:
[2022-10-06 02:04:32,322] {subprocess.py:92} INFO - Compiling artist list...
[2022-10-06 02:04:32,323] {subprocess.py:92} INFO - Loading artists...
[2022-10-06 02:04:32,323] {subprocess.py:92} INFO - 503 artists loaded in 125.79 seconds
[2022-10-06 02:04:32,323] {subprocess.py:92} INFO - Loading tracks...
[2022-10-06 02:04:32,323] {subprocess.py:92} INFO - 2502 tracks loaded in 131.75 seconds
[2022-10-06 02:04:32,332] {subprocess.py:92} INFO - Traceback (most recent call last):
[2022-10-06 02:04:32,332] {subprocess.py:92} INFO -   File "/home/***/.local/lib/python3.7/site-packages/sqlalchemy/engine/base.py", line 3141, in _wrap_pool_connect
[2022-10-06 02:04:32,332] {subprocess.py:92} INFO -     return fn()
[2022-10-06 02:04:32,332] {subprocess.py:92} INFO -   File "/home/***/.local/lib/python3.7/site-packages/sqlalchemy/pool/base.py", line 301, in connect
[2022-10-06 02:04:32,332] {subprocess.py:92} INFO -     return _ConnectionFairy._checkout(self)
[2022-10-06 02:04:32,332] {subprocess.py:92} INFO -   File "/home/***/.local/lib/python3.7/site-packages/sqlalchemy/pool/base.py", line 755, in _checkout
[2022-10-06 02:04:32,332] {subprocess.py:92} INFO -     fairy = _ConnectionRecord.checkout(pool)
[2022-10-06 02:04:32,332] {subprocess.py:92} INFO -   File "/home/***/.local/lib/python3.7/site-packages/sqlalchemy/pool/base.py", line 419, in checkout
[2022-10-06 02:04:32,332] {subprocess.py:92} INFO -     rec = pool._do_get()
[2022-10-06 02:04:32,332] {subprocess.py:92} INFO -   File "/home/***/.local/lib/python3.7/site-packages/sqlalchemy/pool/impl.py", line 145, in _do_get
[2022-10-06 02:04:32,332] {subprocess.py:92} INFO -     self._dec_overflow()
[2022-10-06 02:04:32,333] {subprocess.py:92} INFO -   File "/home/***/.local/lib/python3.7/site-packages/sqlalchemy/util/langhelpers.py", line 72, in __exit__
[2022-10-06 02:04:32,333] {subprocess.py:92} INFO -     with_traceback=exc_tb,
[2022-10-06 02:04:32,333] {subprocess.py:92} INFO -   File "/home/***/.local/lib/python3.7/site-packages/sqlalchemy/util/compat.py", line 211, in raise_
[2022-10-06 02:04:32,333] {subprocess.py:92} INFO -     raise exception
[2022-10-06 02:04:32,333] {subprocess.py:92} INFO -   File "/home/***/.local/lib/python3.7/site-packages/sqlalchemy/pool/impl.py", line 142, in _do_get
[2022-10-06 02:04:32,333] {subprocess.py:92} INFO -     return self._create_connection()
[2022-10-06 02:04:32,333] {subprocess.py:92} INFO -   File "/home/***/.local/lib/python3.7/site-packages/sqlalchemy/pool/base.py", line 247, in _create_connection
[2022-10-06 02:04:32,333] {subprocess.py:92} INFO -     return _ConnectionRecord(self)
[2022-10-06 02:04:32,333] {subprocess.py:92} INFO -   File "/home/***/.local/lib/python3.7/site-packages/sqlalchemy/pool/base.py", line 362, in __init__
[2022-10-06 02:04:32,333] {subprocess.py:92} INFO -     self.__connect(first_connect_check=True)
[2022-10-06 02:04:32,333] {subprocess.py:92} INFO -   File "/home/***/.local/lib/python3.7/site-packages/sqlalchemy/pool/base.py", line 605, in __connect
[2022-10-06 02:04:32,333] {subprocess.py:92} INFO -     pool.logger.debug("Error on connect(): %s", e)
[2022-10-06 02:04:32,333] {subprocess.py:92} INFO -   File "/home/***/.local/lib/python3.7/site-packages/sqlalchemy/util/langhelpers.py", line 72, in __exit__
[2022-10-06 02:04:32,333] {subprocess.py:92} INFO -     with_traceback=exc_tb,
[2022-10-06 02:04:32,333] {subprocess.py:92} INFO -   File "/home/***/.local/lib/python3.7/site-packages/sqlalchemy/util/compat.py", line 211, in raise_
[2022-10-06 02:04:32,333] {subprocess.py:92} INFO -     raise exception
[2022-10-06 02:04:32,333] {subprocess.py:92} INFO -   File "/home/***/.local/lib/python3.7/site-packages/sqlalchemy/pool/base.py", line 599, in __connect
[2022-10-06 02:04:32,333] {subprocess.py:92} INFO -     connection = pool._invoke_creator(self)
[2022-10-06 02:04:32,333] {subprocess.py:92} INFO -   File "/home/***/.local/lib/python3.7/site-packages/sqlalchemy/engine/create.py", line 578, in connect
[2022-10-06 02:04:32,333] {subprocess.py:92} INFO -     return dialect.connect(*cargs, **cparams)
[2022-10-06 02:04:32,333] {subprocess.py:92} INFO -   File "/home/***/.local/lib/python3.7/site-packages/sqlalchemy/engine/default.py", line 583, in connect
[2022-10-06 02:04:32,333] {subprocess.py:92} INFO -     return self.dbapi.connect(*cargs, **cparams)
[2022-10-06 02:04:32,333] {subprocess.py:92} INFO -   File "/home/***/.local/lib/python3.7/site-packages/psycopg2/__init__.py", line 122, in connect
[2022-10-06 02:04:32,333] {subprocess.py:92} INFO -     conn = _connect(dsn, connection_factory=connection_factory, **kwasync)
[2022-10-06 02:04:32,333] {subprocess.py:92} INFO - psycopg2.OperationalError: connection to server at "127.0.0.1", port 5432 failed: Connection refused
[2022-10-06 02:04:32,333] {subprocess.py:92} INFO - 	Is the server running on that host and accepting TCP/IP connections?
[2022-10-06 02:04:32,333] {subprocess.py:92} INFO - 
[2022-10-06 02:04:32,333] {subprocess.py:92} INFO - 
[2022-10-06 02:04:32,333] {subprocess.py:92} INFO - The above exception was the direct cause of the following exception:
[2022-10-06 02:04:32,333] {subprocess.py:92} INFO - 
[2022-10-06 02:04:32,333] {subprocess.py:92} INFO - Traceback (most recent call last):
[2022-10-06 02:04:32,333] {subprocess.py:92} INFO -   File "/opt/***/scripts/load_rappers.py", line 64, in <module>
[2022-10-06 02:04:32,334] {subprocess.py:92} INFO -     Base.metadata.create_all(engine)
[2022-10-06 02:04:32,334] {subprocess.py:92} INFO -   File "/home/***/.local/lib/python3.7/site-packages/sqlalchemy/sql/schema.py", line 4745, in create_all
[2022-10-06 02:04:32,334] {subprocess.py:92} INFO -     ddl.SchemaGenerator, self, checkfirst=checkfirst, tables=tables
[2022-10-06 02:04:32,334] {subprocess.py:92} INFO -   File "/home/***/.local/lib/python3.7/site-packages/sqlalchemy/engine/base.py", line 3007, in _run_ddl_visitor
[2022-10-06 02:04:32,334] {subprocess.py:92} INFO -     with self.begin() as conn:
[2022-10-06 02:04:32,334] {subprocess.py:92} INFO -   File "/home/***/.local/lib/python3.7/site-packages/sqlalchemy/engine/base.py", line 2923, in begin
[2022-10-06 02:04:32,334] {subprocess.py:92} INFO -     conn = self.connect(close_with_result=close_with_result)
[2022-10-06 02:04:32,334] {subprocess.py:92} INFO -   File "/home/***/.local/lib/python3.7/site-packages/sqlalchemy/engine/base.py", line 3095, in connect
[2022-10-06 02:04:32,334] {subprocess.py:92} INFO -     return self._connection_cls(self, close_with_result=close_with_result)
[2022-10-06 02:04:32,334] {subprocess.py:92} INFO -   File "/home/***/.local/lib/python3.7/site-packages/sqlalchemy/engine/base.py", line 91, in __init__
[2022-10-06 02:04:32,334] {subprocess.py:92} INFO -     else engine.raw_connection()
[2022-10-06 02:04:32,334] {subprocess.py:92} INFO -   File "/home/***/.local/lib/python3.7/site-packages/sqlalchemy/engine/base.py", line 3174, in raw_connection
[2022-10-06 02:04:32,334] {subprocess.py:92} INFO -     return self._wrap_pool_connect(self.pool.connect, _connection)
[2022-10-06 02:04:32,334] {subprocess.py:92} INFO -   File "/home/***/.local/lib/python3.7/site-packages/sqlalchemy/engine/base.py", line 3145, in _wrap_pool_connect
[2022-10-06 02:04:32,334] {subprocess.py:92} INFO -     e, dialect, self
[2022-10-06 02:04:32,334] {subprocess.py:92} INFO -   File "/home/***/.local/lib/python3.7/site-packages/sqlalchemy/engine/base.py", line 2004, in _handle_dbapi_exception_noconnection
[2022-10-06 02:04:32,334] {subprocess.py:92} INFO -     sqlalchemy_exception, with_traceback=exc_info[2], from_=e
[2022-10-06 02:04:32,334] {subprocess.py:92} INFO -   File "/home/***/.local/lib/python3.7/site-packages/sqlalchemy/util/compat.py", line 211, in raise_
[2022-10-06 02:04:32,334] {subprocess.py:92} INFO -     raise exception
[2022-10-06 02:04:32,334] {subprocess.py:92} INFO -   File "/home/***/.local/lib/python3.7/site-packages/sqlalchemy/engine/base.py", line 3141, in _wrap_pool_connect
[2022-10-06 02:04:32,334] {subprocess.py:92} INFO -     return fn()
[2022-10-06 02:04:32,334] {subprocess.py:92} INFO -   File "/home/***/.local/lib/python3.7/site-packages/sqlalchemy/pool/base.py", line 301, in connect
[2022-10-06 02:04:32,334] {subprocess.py:92} INFO -     return _ConnectionFairy._checkout(self)
[2022-10-06 02:04:32,334] {subprocess.py:92} INFO -   File "/home/***/.local/lib/python3.7/site-packages/sqlalchemy/pool/base.py", line 755, in _checkout
[2022-10-06 02:04:32,334] {subprocess.py:92} INFO -     fairy = _ConnectionRecord.checkout(pool)
[2022-10-06 02:04:32,334] {subprocess.py:92} INFO -   File "/home/***/.local/lib/python3.7/site-packages/sqlalchemy/pool/base.py", line 419, in checkout
[2022-10-06 02:04:32,334] {subprocess.py:92} INFO -     rec = pool._do_get()
[2022-10-06 02:04:32,334] {subprocess.py:92} INFO -   File "/home/***/.local/lib/python3.7/site-packages/sqlalchemy/pool/impl.py", line 145, in _do_get
[2022-10-06 02:04:32,334] {subprocess.py:92} INFO -     self._dec_overflow()
[2022-10-06 02:04:32,334] {subprocess.py:92} INFO -   File "/home/***/.local/lib/python3.7/site-packages/sqlalchemy/util/langhelpers.py", line 72, in __exit__
[2022-10-06 02:04:32,334] {subprocess.py:92} INFO -     with_traceback=exc_tb,
[2022-10-06 02:04:32,334] {subprocess.py:92} INFO -   File "/home/***/.local/lib/python3.7/site-packages/sqlalchemy/util/compat.py", line 211, in raise_
[2022-10-06 02:04:32,334] {subprocess.py:92} INFO -     raise exception
[2022-10-06 02:04:32,334] {subprocess.py:92} INFO -   File "/home/***/.local/lib/python3.7/site-packages/sqlalchemy/pool/impl.py", line 142, in _do_get
[2022-10-06 02:04:32,335] {subprocess.py:92} INFO -     return self._create_connection()
[2022-10-06 02:04:32,335] {subprocess.py:92} INFO -   File "/home/***/.local/lib/python3.7/site-packages/sqlalchemy/pool/base.py", line 247, in _create_connection
[2022-10-06 02:04:32,335] {subprocess.py:92} INFO -     return _ConnectionRecord(self)
[2022-10-06 02:04:32,335] {subprocess.py:92} INFO -   File "/home/***/.local/lib/python3.7/site-packages/sqlalchemy/pool/base.py", line 362, in __init__
[2022-10-06 02:04:32,335] {subprocess.py:92} INFO -     self.__connect(first_connect_check=True)
[2022-10-06 02:04:32,335] {subprocess.py:92} INFO -   File "/home/***/.local/lib/python3.7/site-packages/sqlalchemy/pool/base.py", line 605, in __connect
[2022-10-06 02:04:32,335] {subprocess.py:92} INFO -     pool.logger.debug("Error on connect(): %s", e)
[2022-10-06 02:04:32,335] {subprocess.py:92} INFO -   File "/home/***/.local/lib/python3.7/site-packages/sqlalchemy/util/langhelpers.py", line 72, in __exit__
[2022-10-06 02:04:32,335] {subprocess.py:92} INFO -     with_traceback=exc_tb,
[2022-10-06 02:04:32,335] {subprocess.py:92} INFO -   File "/home/***/.local/lib/python3.7/site-packages/sqlalchemy/util/compat.py", line 211, in raise_
[2022-10-06 02:04:32,335] {subprocess.py:92} INFO -     raise exception
[2022-10-06 02:04:32,335] {subprocess.py:92} INFO -   File "/home/***/.local/lib/python3.7/site-packages/sqlalchemy/pool/base.py", line 599, in __connect
[2022-10-06 02:04:32,335] {subprocess.py:92} INFO -     connection = pool._invoke_creator(self)
[2022-10-06 02:04:32,335] {subprocess.py:92} INFO -   File "/home/***/.local/lib/python3.7/site-packages/sqlalchemy/engine/create.py", line 578, in connect
[2022-10-06 02:04:32,335] {subprocess.py:92} INFO -     return dialect.connect(*cargs, **cparams)
[2022-10-06 02:04:32,335] {subprocess.py:92} INFO -   File "/home/***/.local/lib/python3.7/site-packages/sqlalchemy/engine/default.py", line 583, in connect
[2022-10-06 02:04:32,335] {subprocess.py:92} INFO -     return self.dbapi.connect(*cargs, **cparams)
[2022-10-06 02:04:32,335] {subprocess.py:92} INFO -   File "/home/***/.local/lib/python3.7/site-packages/psycopg2/__init__.py", line 122, in connect
[2022-10-06 02:04:32,335] {subprocess.py:92} INFO -     conn = _connect(dsn, connection_factory=connection_factory, **kwasync)
[2022-10-06 02:04:32,335] {subprocess.py:92} INFO - sqlalchemy.exc.OperationalError: (psycopg2.OperationalError) connection to server at "127.0.0.1", port 5432 failed: Connection refused
[2022-10-06 02:04:32,335] {subprocess.py:92} INFO - 	Is the server running on that host and accepting TCP/IP connections?
[2022-10-06 02:04:32,335] {subprocess.py:92} INFO - 
[2022-10-06 02:04:32,335] {subprocess.py:92} INFO - (Background on this error at: http://sqlalche.me/e/14/e3q8)
[2022-10-06 02:04:32,411] {subprocess.py:96} INFO - Command exited with return code 1
[2022-10-06 02:04:32,425] {taskinstance.py:1889} ERROR - Task failed with exception
Traceback (most recent call last):
  File "/home/airflow/.local/lib/python3.7/site-packages/airflow/operators/bash.py", line 195, in execute
    f'Bash command failed. The command returned a non-zero exit code {result.exit_code}.'
airflow.exceptions.AirflowException: Bash command failed. The command returned a non-zero exit code 1.
[2022-10-06 02:04:32,430] {taskinstance.py:1400} INFO - Marking task as FAILED. dag_id=load_rappers_dag, task_id=load_rappers, execution_date=20221006T010000, start_date=20221006T020001, end_date=20221006T020432
[2022-10-06 02:04:32,445] {standard_task_runner.py:97} ERROR - Failed to execute job 43 for task load_rappers (Bash command failed. The command returned a non-zero exit code 1.; 8757)
[2022-10-06 02:04:32,455] {local_task_job.py:156} INFO - Task exited with return code 1
[2022-10-06 02:04:32,488] {local_task_job.py:273} INFO - 0 downstream tasks scheduled from follow-on schedule check
[2022-10-07 17:19:21,458] {taskinstance.py:1159} INFO - Dependencies all met for <TaskInstance: load_rappers_dag.load_rappers scheduled__2022-10-06T01:00:00+00:00 [queued]>
[2022-10-07 17:19:21,473] {taskinstance.py:1159} INFO - Dependencies all met for <TaskInstance: load_rappers_dag.load_rappers scheduled__2022-10-06T01:00:00+00:00 [queued]>
[2022-10-07 17:19:21,473] {taskinstance.py:1356} INFO - 
--------------------------------------------------------------------------------
[2022-10-07 17:19:21,473] {taskinstance.py:1357} INFO - Starting attempt 1 of 1
[2022-10-07 17:19:21,473] {taskinstance.py:1358} INFO - 
--------------------------------------------------------------------------------
[2022-10-07 17:19:21,499] {taskinstance.py:1377} INFO - Executing <Task(BashOperator): load_rappers> on 2022-10-06 01:00:00+00:00
[2022-10-07 17:19:21,503] {standard_task_runner.py:52} INFO - Started process 1845 to run task
[2022-10-07 17:19:21,531] {standard_task_runner.py:79} INFO - Running: ['***', 'tasks', 'run', 'load_rappers_dag', 'load_rappers', 'scheduled__2022-10-06T01:00:00+00:00', '--job-id', '28', '--raw', '--subdir', 'DAGS_FOLDER/load_rappers_dag.py', '--cfg-path', '/tmp/tmpgk45xil4', '--error-file', '/tmp/tmpnz06bmxd']
[2022-10-07 17:19:21,539] {standard_task_runner.py:80} INFO - Job 28: Subtask load_rappers
[2022-10-07 17:19:21,785] {task_command.py:369} INFO - Running <TaskInstance: load_rappers_dag.load_rappers scheduled__2022-10-06T01:00:00+00:00 [running]> on host 84650b6b2dfc
[2022-10-07 17:19:21,931] {taskinstance.py:1571} INFO - Exporting the following env vars:
AIRFLOW_CTX_DAG_OWNER=***
AIRFLOW_CTX_DAG_ID=load_rappers_dag
AIRFLOW_CTX_TASK_ID=load_rappers
AIRFLOW_CTX_EXECUTION_DATE=2022-10-06T01:00:00+00:00
AIRFLOW_CTX_TRY_NUMBER=1
AIRFLOW_CTX_DAG_RUN_ID=scheduled__2022-10-06T01:00:00+00:00
[2022-10-07 17:19:21,934] {subprocess.py:62} INFO - Tmp dir root location: 
 /tmp
[2022-10-07 17:19:21,935] {subprocess.py:74} INFO - Running command: ['bash', '-c', 'python ${AIRFLOW_HOME}/scripts/load_rappers.py']
[2022-10-07 17:19:21,949] {subprocess.py:85} INFO - Output:
[2022-10-07 17:21:07,546] {subprocess.py:92} INFO - Compiling artist list...
[2022-10-07 17:21:07,681] {subprocess.py:92} INFO - Loading artists...
[2022-10-07 17:21:07,736] {subprocess.py:92} INFO - Traceback (most recent call last):
[2022-10-07 17:21:07,737] {subprocess.py:92} INFO -   File "/home/***/.local/lib/python3.7/site-packages/urllib3/connectionpool.py", line 710, in urlopen
[2022-10-07 17:21:07,737] {subprocess.py:92} INFO -     chunked=chunked,
[2022-10-07 17:21:07,737] {subprocess.py:92} INFO -   File "/home/***/.local/lib/python3.7/site-packages/urllib3/connectionpool.py", line 386, in _make_request
[2022-10-07 17:21:07,737] {subprocess.py:92} INFO -     self._validate_conn(conn)
[2022-10-07 17:21:07,737] {subprocess.py:92} INFO -   File "/home/***/.local/lib/python3.7/site-packages/urllib3/connectionpool.py", line 1040, in _validate_conn
[2022-10-07 17:21:07,737] {subprocess.py:92} INFO -     conn.connect()
[2022-10-07 17:21:07,737] {subprocess.py:92} INFO -   File "/home/***/.local/lib/python3.7/site-packages/urllib3/connection.py", line 424, in connect
[2022-10-07 17:21:07,737] {subprocess.py:92} INFO -     tls_in_tls=tls_in_tls,
[2022-10-07 17:21:07,737] {subprocess.py:92} INFO -   File "/home/***/.local/lib/python3.7/site-packages/urllib3/util/ssl_.py", line 450, in ssl_wrap_socket
[2022-10-07 17:21:07,737] {subprocess.py:92} INFO -     sock, context, tls_in_tls, server_hostname=server_hostname
[2022-10-07 17:21:07,738] {subprocess.py:92} INFO -   File "/home/***/.local/lib/python3.7/site-packages/urllib3/util/ssl_.py", line 493, in _ssl_wrap_socket_impl
[2022-10-07 17:21:07,738] {subprocess.py:92} INFO -     return ssl_context.wrap_socket(sock, server_hostname=server_hostname)
[2022-10-07 17:21:07,738] {subprocess.py:92} INFO -   File "/usr/local/lib/python3.7/ssl.py", line 423, in wrap_socket
[2022-10-07 17:21:07,738] {subprocess.py:92} INFO -     session=session
[2022-10-07 17:21:07,738] {subprocess.py:92} INFO -   File "/usr/local/lib/python3.7/ssl.py", line 870, in _create
[2022-10-07 17:21:07,738] {subprocess.py:92} INFO -     self.do_handshake()
[2022-10-07 17:21:07,738] {subprocess.py:92} INFO -   File "/usr/local/lib/python3.7/ssl.py", line 1139, in do_handshake
[2022-10-07 17:21:07,738] {subprocess.py:92} INFO -     self._sslobj.do_handshake()
[2022-10-07 17:21:07,738] {subprocess.py:92} INFO - OSError: [Errno 0] Error
[2022-10-07 17:21:07,738] {subprocess.py:92} INFO - 
[2022-10-07 17:21:07,738] {subprocess.py:92} INFO - During handling of the above exception, another exception occurred:
[2022-10-07 17:21:07,738] {subprocess.py:92} INFO - 
[2022-10-07 17:21:07,738] {subprocess.py:92} INFO - Traceback (most recent call last):
[2022-10-07 17:21:07,739] {subprocess.py:92} INFO -   File "/home/***/.local/lib/python3.7/site-packages/requests/adapters.py", line 450, in send
[2022-10-07 17:21:07,739] {subprocess.py:92} INFO -     timeout=timeout
[2022-10-07 17:21:07,739] {subprocess.py:92} INFO -   File "/home/***/.local/lib/python3.7/site-packages/urllib3/connectionpool.py", line 786, in urlopen
[2022-10-07 17:21:07,739] {subprocess.py:92} INFO -     method, url, error=e, _pool=self, _stacktrace=sys.exc_info()[2]
[2022-10-07 17:21:07,739] {subprocess.py:92} INFO -   File "/home/***/.local/lib/python3.7/site-packages/urllib3/util/retry.py", line 550, in increment
[2022-10-07 17:21:07,739] {subprocess.py:92} INFO -     raise six.reraise(type(error), error, _stacktrace)
[2022-10-07 17:21:07,739] {subprocess.py:92} INFO -   File "/home/***/.local/lib/python3.7/site-packages/urllib3/packages/six.py", line 769, in reraise
[2022-10-07 17:21:07,739] {subprocess.py:92} INFO -     raise value.with_traceback(tb)
[2022-10-07 17:21:07,739] {subprocess.py:92} INFO -   File "/home/***/.local/lib/python3.7/site-packages/urllib3/connectionpool.py", line 710, in urlopen
[2022-10-07 17:21:07,739] {subprocess.py:92} INFO -     chunked=chunked,
[2022-10-07 17:21:07,739] {subprocess.py:92} INFO -   File "/home/***/.local/lib/python3.7/site-packages/urllib3/connectionpool.py", line 386, in _make_request
[2022-10-07 17:21:07,739] {subprocess.py:92} INFO -     self._validate_conn(conn)
[2022-10-07 17:21:07,739] {subprocess.py:92} INFO -   File "/home/***/.local/lib/python3.7/site-packages/urllib3/connectionpool.py", line 1040, in _validate_conn
[2022-10-07 17:21:07,739] {subprocess.py:92} INFO -     conn.connect()
[2022-10-07 17:21:07,740] {subprocess.py:92} INFO -   File "/home/***/.local/lib/python3.7/site-packages/urllib3/connection.py", line 424, in connect
[2022-10-07 17:21:07,740] {subprocess.py:92} INFO -     tls_in_tls=tls_in_tls,
[2022-10-07 17:21:07,740] {subprocess.py:92} INFO -   File "/home/***/.local/lib/python3.7/site-packages/urllib3/util/ssl_.py", line 450, in ssl_wrap_socket
[2022-10-07 17:21:07,740] {subprocess.py:92} INFO -     sock, context, tls_in_tls, server_hostname=server_hostname
[2022-10-07 17:21:07,740] {subprocess.py:92} INFO -   File "/home/***/.local/lib/python3.7/site-packages/urllib3/util/ssl_.py", line 493, in _ssl_wrap_socket_impl
[2022-10-07 17:21:07,740] {subprocess.py:92} INFO -     return ssl_context.wrap_socket(sock, server_hostname=server_hostname)
[2022-10-07 17:21:07,740] {subprocess.py:92} INFO -   File "/usr/local/lib/python3.7/ssl.py", line 423, in wrap_socket
[2022-10-07 17:21:07,740] {subprocess.py:92} INFO -     session=session
[2022-10-07 17:21:07,740] {subprocess.py:92} INFO -   File "/usr/local/lib/python3.7/ssl.py", line 870, in _create
[2022-10-07 17:21:07,740] {subprocess.py:92} INFO -     self.do_handshake()
[2022-10-07 17:21:07,741] {subprocess.py:92} INFO -   File "/usr/local/lib/python3.7/ssl.py", line 1139, in do_handshake
[2022-10-07 17:21:07,741] {subprocess.py:92} INFO -     self._sslobj.do_handshake()
[2022-10-07 17:21:07,741] {subprocess.py:92} INFO - urllib3.exceptions.ProtocolError: ('Connection aborted.', OSError(0, 'Error'))
[2022-10-07 17:21:07,741] {subprocess.py:92} INFO - 
[2022-10-07 17:21:07,741] {subprocess.py:92} INFO - During handling of the above exception, another exception occurred:
[2022-10-07 17:21:07,742] {subprocess.py:92} INFO - 
[2022-10-07 17:21:07,742] {subprocess.py:92} INFO - Traceback (most recent call last):
[2022-10-07 17:21:07,742] {subprocess.py:92} INFO -   File "/opt/***/scripts/load_rappers.py", line 82, in <module>
[2022-10-07 17:21:07,743] {subprocess.py:92} INFO -     main()
[2022-10-07 17:21:07,743] {subprocess.py:92} INFO -   File "/opt/***/scripts/load_rappers.py", line 74, in main
[2022-10-07 17:21:07,743] {subprocess.py:92} INFO -     dfRappers = get_artist_data(lister, combinedArtists)
[2022-10-07 17:21:07,743] {subprocess.py:92} INFO -   File "/opt/***/scripts/load_rappers.py", line 43, in get_artist_data
[2022-10-07 17:21:07,743] {subprocess.py:92} INFO -     dfRappers = pd.DataFrame(lister.pull_artist_data(combinedArtists))
[2022-10-07 17:21:07,743] {subprocess.py:92} INFO -   File "/opt/***/scripts/artist_lister.py", line 49, in pull_artist_data
[2022-10-07 17:21:07,743] {subprocess.py:92} INFO -     payload = self.get_artist(i)
[2022-10-07 17:21:07,743] {subprocess.py:92} INFO -   File "/opt/***/scripts/spotify_client.py", line 96, in get_artist
[2022-10-07 17:21:07,743] {subprocess.py:92} INFO -     return self.get_resource(_id, resource_type='artists')
[2022-10-07 17:21:07,743] {subprocess.py:92} INFO -   File "/opt/***/scripts/spotify_client.py", line 81, in get_resource
[2022-10-07 17:21:07,743] {subprocess.py:92} INFO -     r = requests.get(endpoint, headers=headers)
[2022-10-07 17:21:07,743] {subprocess.py:92} INFO -   File "/home/***/.local/lib/python3.7/site-packages/requests/api.py", line 75, in get
[2022-10-07 17:21:07,743] {subprocess.py:92} INFO -     return request('get', url, params=params, **kwargs)
[2022-10-07 17:21:07,744] {subprocess.py:92} INFO -   File "/home/***/.local/lib/python3.7/site-packages/requests/api.py", line 61, in request
[2022-10-07 17:21:07,744] {subprocess.py:92} INFO -     return session.request(method=method, url=url, **kwargs)
[2022-10-07 17:21:07,744] {subprocess.py:92} INFO -   File "/home/***/.local/lib/python3.7/site-packages/requests/sessions.py", line 529, in request
[2022-10-07 17:21:07,744] {subprocess.py:92} INFO -     resp = self.send(prep, **send_kwargs)
[2022-10-07 17:21:07,744] {subprocess.py:92} INFO -   File "/home/***/.local/lib/python3.7/site-packages/requests/sessions.py", line 645, in send
[2022-10-07 17:21:07,744] {subprocess.py:92} INFO -     r = adapter.send(request, **kwargs)
[2022-10-07 17:21:07,744] {subprocess.py:92} INFO -   File "/home/***/.local/lib/python3.7/site-packages/requests/adapters.py", line 501, in send
[2022-10-07 17:21:07,744] {subprocess.py:92} INFO -     raise ConnectionError(err, request=request)
[2022-10-07 17:21:07,744] {subprocess.py:92} INFO - requests.exceptions.ConnectionError: ('Connection aborted.', OSError(0, 'Error'))
[2022-10-07 17:21:13,614] {subprocess.py:96} INFO - Command exited with return code 1
[2022-10-07 17:21:14,472] {taskinstance.py:1889} ERROR - Task failed with exception
Traceback (most recent call last):
  File "/home/airflow/.local/lib/python3.7/site-packages/airflow/operators/bash.py", line 195, in execute
    f'Bash command failed. The command returned a non-zero exit code {result.exit_code}.'
airflow.exceptions.AirflowException: Bash command failed. The command returned a non-zero exit code 1.
[2022-10-07 17:21:14,551] {taskinstance.py:1400} INFO - Marking task as FAILED. dag_id=load_rappers_dag, task_id=load_rappers, execution_date=20221006T010000, start_date=20221007T171921, end_date=20221007T172114
[2022-10-07 17:21:15,084] {standard_task_runner.py:97} ERROR - Failed to execute job 28 for task load_rappers (Bash command failed. The command returned a non-zero exit code 1.; 1845)
[2022-10-07 17:21:15,302] {local_task_job.py:156} INFO - Task exited with return code 1
[2022-10-07 17:21:15,871] {local_task_job.py:273} INFO - 0 downstream tasks scheduled from follow-on schedule check
