[2022-10-07 17:23:07,459] {taskinstance.py:1159} INFO - Dependencies all met for <TaskInstance: load_rappers_dag.load_rappers scheduled__2022-10-07T11:00:00+00:00 [queued]>
[2022-10-07 17:23:07,514] {taskinstance.py:1159} INFO - Dependencies all met for <TaskInstance: load_rappers_dag.load_rappers scheduled__2022-10-07T11:00:00+00:00 [queued]>
[2022-10-07 17:23:07,515] {taskinstance.py:1356} INFO - 
--------------------------------------------------------------------------------
[2022-10-07 17:23:07,516] {taskinstance.py:1357} INFO - Starting attempt 1 of 1
[2022-10-07 17:23:07,516] {taskinstance.py:1358} INFO - 
--------------------------------------------------------------------------------
[2022-10-07 17:23:07,642] {taskinstance.py:1377} INFO - Executing <Task(BashOperator): load_rappers> on 2022-10-07 11:00:00+00:00
[2022-10-07 17:23:07,670] {standard_task_runner.py:52} INFO - Started process 2299 to run task
[2022-10-07 17:23:07,706] {standard_task_runner.py:79} INFO - Running: ['***', 'tasks', 'run', 'load_rappers_dag', 'load_rappers', 'scheduled__2022-10-07T11:00:00+00:00', '--job-id', '62', '--raw', '--subdir', 'DAGS_FOLDER/load_rappers_dag.py', '--cfg-path', '/tmp/tmpko_942f2', '--error-file', '/tmp/tmpgt1g_wcb']
[2022-10-07 17:23:07,723] {standard_task_runner.py:80} INFO - Job 62: Subtask load_rappers
[2022-10-07 17:23:07,988] {task_command.py:369} INFO - Running <TaskInstance: load_rappers_dag.load_rappers scheduled__2022-10-07T11:00:00+00:00 [running]> on host 84650b6b2dfc
[2022-10-07 17:23:08,485] {taskinstance.py:1571} INFO - Exporting the following env vars:
AIRFLOW_CTX_DAG_OWNER=***
AIRFLOW_CTX_DAG_ID=load_rappers_dag
AIRFLOW_CTX_TASK_ID=load_rappers
AIRFLOW_CTX_EXECUTION_DATE=2022-10-07T11:00:00+00:00
AIRFLOW_CTX_TRY_NUMBER=1
AIRFLOW_CTX_DAG_RUN_ID=scheduled__2022-10-07T11:00:00+00:00
[2022-10-07 17:23:08,487] {subprocess.py:62} INFO - Tmp dir root location: 
 /tmp
[2022-10-07 17:23:08,499] {subprocess.py:74} INFO - Running command: ['bash', '-c', 'python ${AIRFLOW_HOME}/scripts/load_rappers.py']
[2022-10-07 17:23:08,548] {subprocess.py:85} INFO - Output:
[2022-10-07 17:23:47,679] {subprocess.py:92} INFO - Compiling artist list...
[2022-10-07 17:23:49,069] {subprocess.py:92} INFO - Traceback (most recent call last):
[2022-10-07 17:23:49,070] {subprocess.py:92} INFO -   File "/home/***/.local/lib/python3.7/site-packages/urllib3/connection.py", line 175, in _new_conn
[2022-10-07 17:23:49,070] {subprocess.py:92} INFO -     (self._dns_host, self.port), self.timeout, **extra_kw
[2022-10-07 17:23:49,070] {subprocess.py:92} INFO -   File "/home/***/.local/lib/python3.7/site-packages/urllib3/util/connection.py", line 72, in create_connection
[2022-10-07 17:23:49,070] {subprocess.py:92} INFO -     for res in socket.getaddrinfo(host, port, family, socket.SOCK_STREAM):
[2022-10-07 17:23:49,070] {subprocess.py:92} INFO -   File "/usr/local/lib/python3.7/socket.py", line 752, in getaddrinfo
[2022-10-07 17:23:49,070] {subprocess.py:92} INFO -     for res in _socket.getaddrinfo(host, port, family, type, proto, flags):
[2022-10-07 17:23:49,070] {subprocess.py:92} INFO - socket.gaierror: [Errno -3] Temporary failure in name resolution
[2022-10-07 17:23:49,075] {subprocess.py:92} INFO - 
[2022-10-07 17:23:49,075] {subprocess.py:92} INFO - During handling of the above exception, another exception occurred:
[2022-10-07 17:23:49,075] {subprocess.py:92} INFO - 
[2022-10-07 17:23:49,076] {subprocess.py:92} INFO - Traceback (most recent call last):
[2022-10-07 17:23:49,076] {subprocess.py:92} INFO -   File "/home/***/.local/lib/python3.7/site-packages/urllib3/connectionpool.py", line 710, in urlopen
[2022-10-07 17:23:49,076] {subprocess.py:92} INFO -     chunked=chunked,
[2022-10-07 17:23:49,076] {subprocess.py:92} INFO -   File "/home/***/.local/lib/python3.7/site-packages/urllib3/connectionpool.py", line 386, in _make_request
[2022-10-07 17:23:49,076] {subprocess.py:92} INFO -     self._validate_conn(conn)
[2022-10-07 17:23:49,076] {subprocess.py:92} INFO -   File "/home/***/.local/lib/python3.7/site-packages/urllib3/connectionpool.py", line 1040, in _validate_conn
[2022-10-07 17:23:49,076] {subprocess.py:92} INFO -     conn.connect()
[2022-10-07 17:23:49,076] {subprocess.py:92} INFO -   File "/home/***/.local/lib/python3.7/site-packages/urllib3/connection.py", line 358, in connect
[2022-10-07 17:23:49,076] {subprocess.py:92} INFO -     self.sock = conn = self._new_conn()
[2022-10-07 17:23:49,076] {subprocess.py:92} INFO -   File "/home/***/.local/lib/python3.7/site-packages/urllib3/connection.py", line 187, in _new_conn
[2022-10-07 17:23:49,077] {subprocess.py:92} INFO -     self, "Failed to establish a new connection: %s" % e
[2022-10-07 17:23:49,077] {subprocess.py:92} INFO - urllib3.exceptions.NewConnectionError: <urllib3.connection.HTTPSConnection object at 0x7f2b32af3410>: Failed to establish a new connection: [Errno -3] Temporary failure in name resolution
[2022-10-07 17:23:49,077] {subprocess.py:92} INFO - 
[2022-10-07 17:23:49,077] {subprocess.py:92} INFO - During handling of the above exception, another exception occurred:
[2022-10-07 17:23:49,077] {subprocess.py:92} INFO - 
[2022-10-07 17:23:49,077] {subprocess.py:92} INFO - Traceback (most recent call last):
[2022-10-07 17:23:49,077] {subprocess.py:92} INFO -   File "/home/***/.local/lib/python3.7/site-packages/requests/adapters.py", line 450, in send
[2022-10-07 17:23:49,077] {subprocess.py:92} INFO -     timeout=timeout
[2022-10-07 17:23:49,077] {subprocess.py:92} INFO -   File "/home/***/.local/lib/python3.7/site-packages/urllib3/connectionpool.py", line 786, in urlopen
[2022-10-07 17:23:49,077] {subprocess.py:92} INFO -     method, url, error=e, _pool=self, _stacktrace=sys.exc_info()[2]
[2022-10-07 17:23:49,078] {subprocess.py:92} INFO -   File "/home/***/.local/lib/python3.7/site-packages/urllib3/util/retry.py", line 592, in increment
[2022-10-07 17:23:49,078] {subprocess.py:92} INFO -     raise MaxRetryError(_pool, url, error or ResponseError(cause))
[2022-10-07 17:23:49,083] {subprocess.py:92} INFO - urllib3.exceptions.MaxRetryError: HTTPSConnectionPool(host='api.spotify.com', port=443): Max retries exceeded with url: /v1/playlists/37i9dQZF1DWY4xHQp97fN6/ (Caused by NewConnectionError('<urllib3.connection.HTTPSConnection object at 0x7f2b32af3410>: Failed to establish a new connection: [Errno -3] Temporary failure in name resolution'))
[2022-10-07 17:23:49,083] {subprocess.py:92} INFO - 
[2022-10-07 17:23:49,094] {subprocess.py:92} INFO - During handling of the above exception, another exception occurred:
[2022-10-07 17:23:49,095] {subprocess.py:92} INFO - 
[2022-10-07 17:23:49,096] {subprocess.py:92} INFO - Traceback (most recent call last):
[2022-10-07 17:23:49,096] {subprocess.py:92} INFO -   File "/opt/***/scripts/load_rappers.py", line 82, in <module>
[2022-10-07 17:23:49,096] {subprocess.py:92} INFO -     main()
[2022-10-07 17:23:49,096] {subprocess.py:92} INFO -   File "/opt/***/scripts/load_rappers.py", line 73, in main
[2022-10-07 17:23:49,096] {subprocess.py:92} INFO -     combinedArtists = compile_artists(lister, genreDict, playlistDict)
[2022-10-07 17:23:49,096] {subprocess.py:92} INFO -   File "/opt/***/scripts/load_rappers.py", line 38, in compile_artists
[2022-10-07 17:23:49,096] {subprocess.py:92} INFO -     return lister.combine_artists(genreDict, playlistDict)
[2022-10-07 17:23:49,097] {subprocess.py:92} INFO -   File "/opt/***/scripts/artist_lister.py", line 40, in combine_artists
[2022-10-07 17:23:49,097] {subprocess.py:92} INFO -     artistDict = self.union_dict(artistDict, self.parse_playlist(k))
[2022-10-07 17:23:49,097] {subprocess.py:92} INFO -   File "/opt/***/scripts/artist_lister.py", line 22, in parse_playlist
[2022-10-07 17:23:49,097] {subprocess.py:92} INFO -     rows = len(self.get_playlist(playlist_id)['tracks']['items'])
[2022-10-07 17:23:49,097] {subprocess.py:92} INFO -   File "/opt/***/scripts/spotify_client.py", line 105, in get_playlist
[2022-10-07 17:23:49,097] {subprocess.py:92} INFO -     return self.get_resource(_id, resource_type='playlists')
[2022-10-07 17:23:49,097] {subprocess.py:92} INFO -   File "/opt/***/scripts/spotify_client.py", line 81, in get_resource
[2022-10-07 17:23:49,097] {subprocess.py:92} INFO -     r = requests.get(endpoint, headers=headers)
[2022-10-07 17:23:49,097] {subprocess.py:92} INFO -   File "/home/***/.local/lib/python3.7/site-packages/requests/api.py", line 75, in get
[2022-10-07 17:23:49,098] {subprocess.py:92} INFO -     return request('get', url, params=params, **kwargs)
[2022-10-07 17:23:49,098] {subprocess.py:92} INFO -   File "/home/***/.local/lib/python3.7/site-packages/requests/api.py", line 61, in request
[2022-10-07 17:23:49,098] {subprocess.py:92} INFO -     return session.request(method=method, url=url, **kwargs)
[2022-10-07 17:23:49,098] {subprocess.py:92} INFO -   File "/home/***/.local/lib/python3.7/site-packages/requests/sessions.py", line 529, in request
[2022-10-07 17:23:49,098] {subprocess.py:92} INFO -     resp = self.send(prep, **send_kwargs)
[2022-10-07 17:23:49,098] {subprocess.py:92} INFO -   File "/home/***/.local/lib/python3.7/site-packages/requests/sessions.py", line 645, in send
[2022-10-07 17:23:49,098] {subprocess.py:92} INFO -     r = adapter.send(request, **kwargs)
[2022-10-07 17:23:49,098] {subprocess.py:92} INFO -   File "/home/***/.local/lib/python3.7/site-packages/requests/adapters.py", line 519, in send
[2022-10-07 17:23:49,098] {subprocess.py:92} INFO -     raise ConnectionError(e, request=request)
[2022-10-07 17:23:49,098] {subprocess.py:92} INFO - requests.exceptions.ConnectionError: HTTPSConnectionPool(host='api.spotify.com', port=443): Max retries exceeded with url: /v1/playlists/37i9dQZF1DWY4xHQp97fN6/ (Caused by NewConnectionError('<urllib3.connection.HTTPSConnection object at 0x7f2b32af3410>: Failed to establish a new connection: [Errno -3] Temporary failure in name resolution'))
[2022-10-07 17:23:51,436] {subprocess.py:96} INFO - Command exited with return code 1
[2022-10-07 17:23:51,669] {taskinstance.py:1889} ERROR - Task failed with exception
Traceback (most recent call last):
  File "/home/airflow/.local/lib/python3.7/site-packages/airflow/operators/bash.py", line 195, in execute
    f'Bash command failed. The command returned a non-zero exit code {result.exit_code}.'
airflow.exceptions.AirflowException: Bash command failed. The command returned a non-zero exit code 1.
[2022-10-07 17:23:51,783] {taskinstance.py:1400} INFO - Marking task as FAILED. dag_id=load_rappers_dag, task_id=load_rappers, execution_date=20221007T110000, start_date=20221007T172307, end_date=20221007T172351
[2022-10-07 17:23:51,919] {standard_task_runner.py:97} ERROR - Failed to execute job 62 for task load_rappers (Bash command failed. The command returned a non-zero exit code 1.; 2299)
[2022-10-07 17:23:51,988] {local_task_job.py:156} INFO - Task exited with return code 1
[2022-10-07 17:23:52,186] {local_task_job.py:273} INFO - 0 downstream tasks scheduled from follow-on schedule check
